<?xml version="1.0"?>
<robot name="robbie">
        <link name="base_link">
                <visual>
                        <origin xyz="0 0 0.10" rpy="0 0 0" />
                                <geometry>
                                        <box size="0.41 0.34 0.20" />
                                </geometry>
                        <material name="Cyan1">
                                <color rgba="0 1 1 1.0"/>
                        </material>
                </visual>
        </link>
       
        <link name="base_laser">
                <visual>
                        <origin xyz="0 0 .05" rpy="0 0 0" />
                                <geometry>
                                        <cylinder radius="0.025" length="0.10" />
                                </geometry>
                                <material name="black">
                                        <color rgba="0 0 0 1"/>
                                </material>
                </visual>
        </link>
         
        <link name="torso_link">
                <visual>
                        <origin xyz="0 0 0.075" rpy="0 0 0" />
                        <geometry>
                                <box size="0.075 0.15 0.15" />
                        </geometry>
                        <material name="Cyan2">
                                <color rgba="0 0.5 0.5 0"/>
                        </material>
                </visual>
        </link>

         <link name="head_pan_link">
                <visual>
                        <origin xyz="0 0 0.0225" rpy="0 0 0" />
                        <geometry>
                                <box size="0.055 0.032 0.048" />
                        </geometry>
                <material name="Green1">
                                <color rgba="0 1 0 1.0"/>
                        </material>
                </visual>
                <collision>
                        <origin xyz="0 0 0.0225" rpy="0 0 0" />
                        <geometry>
                                <box size="0.055 0.032 0.048" />
                        </geometry>
                </collision>
      
        </link>
        
        <link name="head_tilt_link">
                <visual>
                        <origin xyz="0 0 0.02" rpy="0 0 0" />
                        <geometry>
                                <box size="0.032 0.047 0.07" />
                        </geometry>
                <material name="Green2">
                                <color rgba="0.1 0.8 0 1.0"/>
                        </material>
                </visual>
                <collision>
                        <origin xyz="0 0 0.02" rpy="0 0 0" />
                        <geometry>
                                <box size="0.032 0.047 0.07" />
                        </geometry>
                </collision>
        <inertial>
                <mass value="1" />
                <inertia ixx="1.0" ixy="0.0" ixz="0.0"
                         iyy="1.0" iyz="0.0"
                         izz="1.0" />
        </inertial>
        </link>
  
        <link name="head_link">
                <visual>
                        <origin xyz="0 0 0.03" rpy="0 0 0" />
                        <geometry>
                                <box size="0.055 0.2 0.075" />
                        </geometry>
                        <material name="white">
                                <color rgba="1 1 1 1"/>
                        </material>
                </visual>
                <collision>
                    <origin xyz="0 0 0.03" rpy="0 0 0" />
                        <geometry>
                                <box size="0.055 0.2 0.075" />
                        </geometry>             
                </collision>

        </link>

	
        
        <link name="right_shoulder_link">
                <visual>
                        <origin xyz="0 0 0" rpy="0 0 0" />
                        <geometry>
                                <box size="0.032 0.068 0.037" />
                        </geometry>
                <material name="Green1">
                                <color rgba="0 1 0 1.0"/>
                        </material>
                </visual>
                <collision>
                        <origin xyz="0 0 0" rpy="0 0 0" />
                        <geometry>
                                <box size="0.032 0.068 0.037" />
                        </geometry>
                </collision>
        <inertial>
                <mass value="2" />
                <inertia ixx="1.0" ixy="0.0" ixz="0.0"
                         iyy="1.0" iyz="0.0"
                         izz="1.0" />
        </inertial>
        </link>

    
                
        <link name="right_shoulder_forward_link">
                <visual>
                        <origin xyz="0 0.0 0" rpy="0 0 0" />
                        <geometry>
                                <box size="0.055 0.037 0.032" />
                        </geometry>
                <material name="Blue1">
                                <color rgba="0 0 0.9 1.0"/>
                        </material>
                </visual>
                <collision>
                        <origin xyz="0 0.0 0" rpy="0 0 0" />
                        <geometry>
                                <box size="0.055 0.037 0.032" />
                        </geometry>
                </collision>
        <inertial>
                <mass value="2" />
                <inertia ixx="1.0" ixy="0.0" ixz="0.0"
                         iyy="1.0" iyz="0.0"
                         izz="1.0" />
        </inertial>
        </link>

        <link name="right_shoulder_up_link">
                <visual>
                        <origin xyz="0 0.004 -0.018" rpy="1.57 0 0" />
                        <geometry>
                                <box size="0.03 0.052 0.03" />
                        </geometry>
                <material name="Blue2">
                                <color rgba="0 0 0.7 1.0"/>
                        </material>
                </visual>
                <collision>
                        <origin xyz="0 0.004 -0.018" rpy="1.57 0 0" />
                        <geometry>
                                <box size="0.03 0.052 0.03" />
                        </geometry>
                </collision>
        <inertial>
                <mass value="2" />
                <inertia ixx="1.0" ixy="0.0" ixz="0.0"
                         iyy="1.0" iyz="0.0"
                         izz="1.0" />
        </inertial>
        </link>

       <link name="right_upper_arm_link">
                <visual>
                        <geometry>
                                <cylinder radius="0.0075" length="0.053" />
                        </geometry>
                <material name="Grey1">
                                <color rgba="0.9 0.9 0.9 1.0"/>
                        </material>
                </visual>
                <collision>
                        <geometry>
                                <cylinder radius="0.0075" length="0.053" />
                        </geometry>
                </collision>
        <inertial>
                <mass value="3" />
                <inertia ixx="1.0" ixy="0.0" ixz="0.0"
                         iyy="1.0" iyz="0.0"
                         izz="1.0" />
        </inertial>
        </link>

       <link name="right_elbow_link">
                <visual>
                        <origin xyz="-0.014 0 0.012" rpy="0 0 1.57" />
                        <geometry>
                                <box size="0.03 0.05 0.03" />
                        </geometry>
                <material name="Blue2">
                                <color rgba="0 0 0.7 1.0"/>
                        </material>
                </visual>
                <collision>
                        <origin xyz="-0.014 0 0.012" rpy="0 0 1.57" />
                        <geometry>
                                <box size="0.03 0.05 0.03" />
                        </geometry>
                </collision>
        <inertial>
                <mass value="1" />
                <inertia ixx="1.0" ixy="0.0" ixz="0.0"
                         iyy="1.0" iyz="0.0"
                         izz="1.0" />
        </inertial>
        </link>

       <link name="right_lower_arm_link">
                <visual>
                        <geometry>
                                <cylinder radius="0.0075" length="0.092" />
                        </geometry>
                <material name="Grey1">
                                <color rgba="0.9 0.9 0.9 1.0"/>
                        </material>
                </visual>
                <collision>
                        <geometry>
                                <cylinder radius="0.0075" length="0.092" />
                        </geometry>
                </collision>
        <inertial>
                <mass value="2" />
                <inertia ixx="1.0" ixy="0.0" ixz="0.0"
                         iyy="1.0" iyz="0.0"
                         izz="1.0" />
        </inertial>
        </link>

      <link name="right_wrist_bracket_link">
                <visual>
                        <origin xyz="0 0 0" rpy="0 0 0" />
                        <geometry>
                                <box size="0.05 0.025 0.038" />
                        </geometry>
                <material name="Green1">
                                <color rgba="0 1 0 1.0"/>
                        </material>
                </visual>
                <collision>
                        <origin xyz="0 0 0" rpy="0 0 0" />
                        <geometry>
                                <box size="0.05 0.025 0.038" />
                        </geometry>
                </collision>
        <inertial>
                <mass value="2" />
                <inertia ixx="1.0" ixy="0.0" ixz="0.0"
                         iyy="1.0" iyz="0.0"
                         izz="1.0" />
        </inertial>
        </link>
      
         <link name="right_wrist_link">
                <visual>
                        <origin xyz="0 0 0" rpy="1.57 0 0" />
                        <geometry>
                                <box size="0.03 0.05 0.03" />
                        </geometry>
                <material name="Blue2">
                                <color rgba="0 0 0.7 1.0"/>
                        </material>
                </visual>
                <collision>
                        <origin xyz="0 0 0" rpy="1.57 0 0" />
                        <geometry>
                                <box size="0.03 0.05 0.03" />
                        </geometry>
                </collision>
        <inertial>
                <mass value="1" />
                <inertia ixx="1.0" ixy="0.0" ixz="0.0"
                         iyy="1.0" iyz="0.0"
                         izz="1.0" />
        </inertial>
        </link>
        
      
        <link name="right_hand_link">
                <visual>
                        <geometry>
                                <box size="0.164 0.01 0.035" />
                        </geometry>
                <material name="Grey1">
                                <color rgba="0.9 0.9 0.9 1.0"/>
                        </material>
                </visual>
                <collision>
                        <geometry>
                                <box size="0.164 0.01 0.035" />
                        </geometry>
                </collision>
        <inertial>
                <mass value="1" />
                <inertia ixx="1.0" ixy="0.0" ixz="0.0"
                         iyy="1.0" iyz="0.0"
                         izz="1.0" />
        </inertial>
        </link>
        
        <!-- * * * Joint Definitions * * * -->


  <joint name="joint1" type="fixed">
    <parent link="base_link"/>
    <child link="base_laser"/>
    <origin xyz="0.21 0.0 .05" rpy="0 0 0" />
  </joint>

  <joint name="joint2" type="fixed">
    <parent link="base_link"/>
    <child link="torso_link"/>
    <origin xyz="0.15 0 0.2" rpy="0 0 0" />
  </joint>

  <joint name="head_pan_joint" type="revolute">
    <parent link="torso_link"/>
    <child link="head_pan_link"/>
    <origin xyz="0 0 .15" rpy="0 0 0" />
    <axis xyz="0 0 1" />
    <limit lower="-3.1416" upper="3.1416" effort="10" velocity="3" />
  </joint>

   <joint name="head_tilt_joint" type="revolute">
        <parent link="head_pan_link" />
        <child link="head_tilt_link" />
        <origin xyz="0 0 0.04" rpy="0 0 0" />
        <axis xyz="0 1 0" />
        <limit lower="-1.57" upper="1.57" effort="10" velocity="3" />
        </joint>

  <joint name="head_link_joint" type="fixed">
    <parent link="head_tilt_link"/>
    <child link="head_link"/>
    <origin xyz="0 0 0.04" rpy="0 0 0" />
    <axis xyz="0 0 0" />
    <limit lower="-3.1416" upper="3.1416" effort="10" velocity="3" />
  </joint>

     <joint name="right_shoulder_joint" type="revolute">
        <parent link="torso_link" />
        <child link="right_shoulder_link" />
        <origin xyz=" 0 -0.1 0.105" rpy="0 0 0" />
        <limit lower="0" upper="4.7" effort="10" velocity="3" />
        <axis xyz="0 0 1" />
     </joint>
   
        <joint name="right_shoulder_forward_joint" type="revolute">
        <parent link="right_shoulder_link" />
        <child link="right_shoulder_forward_link" />
        <origin xyz="0.01 -0.05 0" rpy="0 0 0" />
        <limit lower="-1.2" upper="1.2" effort="10" velocity="3" />
        <axis xyz="0 -1 0" />
        </joint>
        
        
        <joint name="right_shoulder_up_joint" type="revolute">
        <parent link="right_shoulder_forward_link" />
        <child link="right_shoulder_up_link" />
        <origin xyz="0 -0.058 0" rpy="0 -1.57 0" />
        <limit lower="-1.57" upper="1.57" effort="10" velocity="3" />
        <axis xyz="0 1 0" />
        </joint>
        
        
        
        <joint name="right_upper_arm_joint" type="fixed">
        <parent link="right_shoulder_up_link" />
        <child link="right_upper_arm_link" />
        <origin xyz="0 0 -0.07" rpy="0 0 0" />
        </joint>
        
        
        
        <joint name="right_elbow_joint" type="revolute">
        <parent link="right_upper_arm_link" />
        <child link="right_elbow_link" />
        <origin xyz="0 0 -0.053" rpy="0 0 0" />
        <limit lower="-1.57" upper="1.57" effort="10" velocity="3" />
        <axis xyz="0 0 1" />
        </joint>
        
        
        
        <joint name="right_lower_arm_joint" type="fixed">
        <parent link="right_elbow_link" />
        <child link="right_lower_arm_link" />
        <origin xyz="-0.015 0 -0.045" rpy="0 0 0" />
        </joint>
        
                
        <joint name="right_wrist_bracket_joint" type="fixed">
        <parent link="right_lower_arm_link" />
        <child link="right_wrist_bracket_link" />
        <origin xyz="0 0 -0.065" rpy="0 0 0" />
        </joint>
        
        
        
        <joint name="right_wrist_joint" type="fixed">
        <parent link="right_wrist_bracket_link" />
        <child link="right_wrist_link" />
        <origin xyz="0 0 -0.025" rpy="0 0 0" />
        <limit lower="-1.57" upper="1.57" effort="10" velocity="3" />
        <axis xyz="1 0 0" />
        </joint>
        
       
        <joint name="right_hand_joint" type="fixed">
        <parent link="right_wrist_link" />
        <child link="right_hand_link" />
        <origin xyz="0.11 0 0" rpy="0 0 0" />
        </joint>



</robot>

