<?xml version="1.0" ?>
<!-- =================================================================================== -->
<!-- |    This document was autogenerated by xacro from robbie_long.xacro              | -->
<!-- |    EDITING THIS FILE BY HAND IS NOT RECOMMENDED                                 | -->
<!-- =================================================================================== -->
<!-- XML namespaces -->
<robot name="robbie" xmlns:controller="http://playerstage.sourceforge.net/gazebo/xmlschema/#controller" xmlns:interface="http://playerstage.sourceforge.net/gazebo/xmlschema/#interface" xmlns:sensor="http://playerstage.sourceforge.net/gazebo/xmlschema/#sensor" xmlns:xacro="http://ros.org/wiki/xacro">
  <!-- ============================  A Few Color Macros  ============================ -->
  <!-- ============================   A Few Shape Macros  ============================ -->
  <!-- ============================   Link Definitions  ============================ -->
  <link name="base_link">
    <visual>
      <origin rpy="0 0 0" xyz="0 0 .17"/>
      <geometry>
        <box size="0.4 0.34 0.23"/>
      </geometry>
      <material name="green1">
        <color rgba="0 1 0 1.0"/>
      </material>
    </visual>
    <collision>
      <origin rpy="0 0 0" xyz="0 0 .17"/>
      <geometry>
        <box size="0.4 0.34 0.23"/>
      </geometry>
    </collision>
    <inertial>
      <mass value="0.1"/>
      <inertia ixx="0.001" ixy="0.0" ixz="0.0" iyy="0.001" iyz="0.0" izz="0.001"/>
    </inertial>
  </link>
  <gazebo reference="base_link">
    <material>Gazebo/FlatBlack</material>
    <selfCollide>false</selfCollide>
    <turnGravityOff>true</turnGravityOff>
  </gazebo>
  <link name="r_wheel_link">
    <visual>
      <origin rpy="1.57 0 0" xyz="0 0 0"/>
      <geometry>
        <cylinder length="0.04" radius="0.075"/>
      </geometry>
      <material name="black">
        <color rgba="0.1 0.1 0.1 1.0"/>
      </material>
    </visual>
    <collision>
      <origin rpy="1.57 0 0" xyz="0 0 0"/>
      <geometry>
        <cylinder length="0.04" radius="0.075"/>
      </geometry>
    </collision>
    <inertial>
      <mass value="0.1"/>
      <inertia ixx="0.001" ixy="0.0" ixz="0.0" iyy="0.001" iyz="0.0" izz="0.001"/>
    </inertial>
  </link>
  <gazebo reference="r_wheel_link">
    <material>Gazebo/FlatBlack</material>
    <selfCollide>false</selfCollide>
    <turnGravityOff>true</turnGravityOff>
  </gazebo>
  <link name="l_wheel_link">
    <visual>
      <origin rpy="1.57 0 0" xyz="0 0 0"/>
      <geometry>
        <cylinder length="0.04" radius="0.075"/>
      </geometry>
      <material name="black">
        <color rgba="0.1 0.1 0.1 1.0"/>
      </material>
    </visual>
    <collision>
      <origin rpy="1.57 0 0" xyz="0 0 0"/>
      <geometry>
        <cylinder length="0.04" radius="0.075"/>
      </geometry>
    </collision>
    <inertial>
      <mass value="0.1"/>
      <inertia ixx="0.001" ixy="0.0" ixz="0.0" iyy="0.001" iyz="0.0" izz="0.001"/>
    </inertial>
  </link>
  <gazebo reference="l_wheel_link">
    <material>Gazebo/FlatBlack</material>
    <selfCollide>false</selfCollide>
    <turnGravityOff>true</turnGravityOff>
  </gazebo>
  <link name="deck_link">
    <visual>
      <origin rpy="0 0 0" xyz="0 0 0"/>
      <geometry>
        <box size="0.4 0.2 0.09"/>
      </geometry>
      <material name="blue1">
        <color rgba="0 0 0.9 1.0"/>
      </material>
    </visual>
    <collision>
      <origin rpy="0 0 0" xyz="0 0 0"/>
      <geometry>
        <box size="0.4 0.2 0.09"/>
      </geometry>
    </collision>
    <inertial>
      <mass value="0.1"/>
      <inertia ixx="0.001" ixy="0.0" ixz="0.0" iyy="0.001" iyz="0.0" izz="0.001"/>
    </inertial>
  </link>
  <gazebo reference="deck_link">
    <material>Gazebo/FlatBlack</material>
    <selfCollide>false</selfCollide>
    <turnGravityOff>true</turnGravityOff>
  </gazebo>
  <!-- shoulder_pan_joint joint-->
  <link name="arm_shoulder_tilt_link">
    <visual>
      <origin rpy="0 0 0" xyz="0 0 0"/>
      <geometry>
        <box size="0.075 0.2 0.007"/>
      </geometry>
      <material name="cyan3">
        <color rgba="0 0.5 0.5 1.0"/>
      </material>
    </visual>
    <collision>
      <origin rpy="0 0 0" xyz="0 0 0"/>
      <geometry>
        <box size="0.075 0.2 0.007"/>
      </geometry>
    </collision>
    <inertial>
      <mass value="2.91"/>
      <inertia ixx="0.001" ixy="0.0" ixz="0.0" iyy="0.001" iyz="0.0" izz="0.001"/>
    </inertial>
  </link>
  <gazebo reference="arm_shoulder_tilt_link">
    <material>Gazebo/Grey</material>
    <selfCollide>false</selfCollide>
    <turnGravityOff>true</turnGravityOff>
  </gazebo>
  <!-- arm_lift_joint joint-->
  <link name="arm_tilt_servo">
    <visual>
      <origin rpy="0 0 0" xyz="0 0 0"/>
      <geometry>
        <mesh filename="package://robbie/meshes/ax12_box2.stl" scale="0.001 0.001 0.001"/>
      </geometry>
      <material name="ax12_color">
        <color rgba="0.1 0.1 0.1 1.0"/>
      </material>
    </visual>
    <collision>
      <origin rpy="0 0 0" xyz="0 0 0"/>
      <geometry>
        <box size="0.032 0.038 0.05"/>
        <!--
					<mesh filename="package://robbie/meshes/ax12_box2.${MESH_EXT}" scale="${M_SCALE} ${M_SCALE} ${M_SCALE}"/>
					-->
      </geometry>
    </collision>
    <inertial>
      <mass value="0.055"/>
      <inertia ixx="0.001" ixy="0.0" ixz="0.0" iyy="0.001" iyz="0.0" izz="0.001"/>
    </inertial>
  </link>
  <gazebo reference="arm_tilt_servo">
    <material>Gazebo/FlatBlack</material>
    <selfCollide>false</selfCollide>
    <turnGravityOff>true</turnGravityOff>
  </gazebo>
  <link name="arm_tilt_f3">
    <visual>
      <origin rpy="0 0 0" xyz="0 0 0"/>
      <geometry>
        <mesh filename="package://robbie/meshes/F3.stl" scale="0.001 0.001 0.001"/>
      </geometry>
      <material name="bracket_color">
        <color rgba="0.9 0.9 0.9 1.0"/>
      </material>
    </visual>
    <collision>
      <origin rpy="0 0 0" xyz="0 0 0"/>
      <geometry>
        <!--
          				<mesh filename="package://robbie/meshes/F3.${MESH_EXT}" scale="${M_SCALE} ${M_SCALE} ${M_SCALE}"/>
						-->
        <box size="0.025 0.04 0.009"/>
      </geometry>
    </collision>
    <inertial>
      <mass value="0.01"/>
      <inertia ixx="0.001" ixy="0.0" ixz="0.0" iyy="0.001" iyz="0.0" izz="0.001"/>
    </inertial>
  </link>
  <gazebo reference="arm_tilt_f3">
    <material>Gazebo/WhiteEmissive</material>
    <selfCollide>false</selfCollide>
    <turnGravityOff>true</turnGravityOff>
  </gazebo>
  <link name="arm_extension_f3">
    <visual>
      <origin rpy="-1.57 0 0" xyz="0 0 0"/>
      <geometry>
        <mesh filename="package://robbie/meshes/F3.stl" scale="0.001 0.001 0.001"/>
      </geometry>
      <material name="bracket_color">
        <color rgba="0.9 0.9 0.9 1.0"/>
      </material>
    </visual>
    <collision>
      <origin rpy="-1.57 0 0" xyz="0 0 0"/>
      <geometry>
        <!--
          				<mesh filename="package://robbie/meshes/F3.${MESH_EXT}" scale="${M_SCALE} ${M_SCALE} ${M_SCALE}"/>
						-->
        <box size="0.025 0.04 0.009"/>
      </geometry>
    </collision>
    <inertial>
      <mass value="0.01"/>
      <inertia ixx="0.001" ixy="0.0" ixz="0.0" iyy="0.001" iyz="0.0" izz="0.001"/>
    </inertial>
  </link>
  <gazebo reference="arm_extension_f3">
    <material>Gazebo/WhiteEmissive</material>
    <selfCollide>false</selfCollide>
    <turnGravityOff>true</turnGravityOff>
  </gazebo>
  <link name="arm_extension_1">
    <visual>
      <origin rpy="0 0 0" xyz="0 0 0"/>
      <geometry>
        <box size="0.23 0.019 0.019"/>
      </geometry>
      <material name="green1">
        <color rgba="0 1 0 1.0"/>
      </material>
    </visual>
    <collision>
      <origin rpy="0 0 0" xyz="0 0 0"/>
      <geometry>
        <box size="0.23 0.019 0.019"/>
      </geometry>
    </collision>
    <inertial>
      <mass value="0.1"/>
      <inertia ixx="0.001" ixy="0.0" ixz="0.0" iyy="0.001" iyz="0.0" izz="0.001"/>
    </inertial>
  </link>
  <gazebo reference="arm_extension_1">
    <material>Gazebo/FlatBlack</material>
    <selfCollide>false</selfCollide>
    <turnGravityOff>true</turnGravityOff>
  </gazebo>
  <!-- elbow_tilt_joint-->
  <link name="elbow_tilt_servo">
    <visual>
      <origin rpy="0 1.57 0" xyz="0 0 0"/>
      <geometry>
        <mesh filename="package://robbie/meshes/ax12_box2.stl" scale="0.001 0.001 0.001"/>
      </geometry>
      <material name="ax12_color">
        <color rgba="0.1 0.1 0.1 1.0"/>
      </material>
    </visual>
    <collision>
      <origin rpy="0 1.57 0" xyz="0 0 0"/>
      <geometry>
        <box size="0.032 0.038 0.05"/>
        <!--
					<mesh filename="package://robbie/meshes/ax12_box2.${MESH_EXT}" scale="${M_SCALE} ${M_SCALE} ${M_SCALE}"/>
					-->
      </geometry>
    </collision>
    <inertial>
      <mass value="0.055"/>
      <inertia ixx="0.001" ixy="0.0" ixz="0.0" iyy="0.001" iyz="0.0" izz="0.001"/>
    </inertial>
  </link>
  <gazebo reference="elbow_tilt_servo">
    <material>Gazebo/FlatBlack</material>
    <selfCollide>false</selfCollide>
    <turnGravityOff>true</turnGravityOff>
  </gazebo>
  <link name="elbow_bracket_f3">
    <visual>
      <origin rpy="3.1415 0 1.57" xyz="0 0 0"/>
      <geometry>
        <mesh filename="package://robbie/meshes/F3.stl" scale="0.001 0.001 0.001"/>
      </geometry>
      <material name="bracket_color">
        <color rgba="0.9 0.9 0.9 1.0"/>
      </material>
    </visual>
    <collision>
      <origin rpy="3.1415 0 1.57" xyz="0 0 0"/>
      <geometry>
        <!--
          				<mesh filename="package://robbie/meshes/F3.${MESH_EXT}" scale="${M_SCALE} ${M_SCALE} ${M_SCALE}"/>
						-->
        <box size="0.025 0.04 0.009"/>
      </geometry>
    </collision>
    <inertial>
      <mass value="0.01"/>
      <inertia ixx="0.001" ixy="0.0" ixz="0.0" iyy="0.001" iyz="0.0" izz="0.001"/>
    </inertial>
  </link>
  <gazebo reference="elbow_bracket_f3">
    <material>Gazebo/WhiteEmissive</material>
    <selfCollide>false</selfCollide>
    <turnGravityOff>true</turnGravityOff>
  </gazebo>
  <link name="elbow_bracket_f2">
    <visual>
      <origin rpy="0 1.57 0" xyz="0 0 0"/>
      <geometry>
        <mesh filename="package://robbie/meshes/F2.stl" scale="0.001 0.001 0.001"/>
      </geometry>
      <material name="bracket_color">
        <color rgba="0.9 0.9 0.9 1.0"/>
      </material>
    </visual>
    <collision>
      <origin rpy="0 1.57 0" xyz="0 0 0"/>
      <geometry>
        <box size="0.026 0.05 0.038"/>
        <!--
          				<mesh filename="package://robbie/meshes/F2.${MESH_EXT}" scale="${M_SCALE} ${M_SCALE} ${M_SCALE}"/>
          				-->
      </geometry>
    </collision>
    <inertial>
      <mass value="0.02"/>
      <inertia ixx="0.001" ixy="0.0" ixz="0.0" iyy="0.001" iyz="0.0" izz="0.001"/>
    </inertial>
  </link>
  <gazebo reference="elbow_bracket_f2">
    <material>Gazebo/WhiteEmissive</material>
    <selfCollide>false</selfCollide>
    <turnGravityOff>true</turnGravityOff>
  </gazebo>
  <link name="arm_extension_2">
    <visual>
      <origin rpy="0 0 0" xyz="0 0 0"/>
      <geometry>
        <box size="0.23 0.019 0.019"/>
      </geometry>
      <material name="green1">
        <color rgba="0 1 0 1.0"/>
      </material>
    </visual>
    <collision>
      <origin rpy="0 0 0" xyz="0 0 0"/>
      <geometry>
        <box size="0.23 0.019 0.019"/>
      </geometry>
    </collision>
    <inertial>
      <mass value="0.1"/>
      <inertia ixx="0.001" ixy="0.0" ixz="0.0" iyy="0.001" iyz="0.0" izz="0.001"/>
    </inertial>
  </link>
  <gazebo reference="arm_extension_2">
    <material>Gazebo/FlatBlack</material>
    <selfCollide>false</selfCollide>
    <turnGravityOff>true</turnGravityOff>
  </gazebo>
  <!-- Elbow roll joint-->
  <link name="elbow_roll_f1__link">
    <visual>
      <origin rpy="3.1415 0 1.57" xyz="0 0 0"/>
      <geometry>
        <mesh filename="package://robbie/meshes/F3.stl" scale="0.001 0.001 0.001"/>
      </geometry>
      <material name="bracket_color">
        <color rgba="0.9 0.9 0.9 1.0"/>
      </material>
    </visual>
    <collision>
      <origin rpy="3.1415 0 1.57" xyz="0 0 0"/>
      <geometry>
        <!--
          				<mesh filename="package://robbie/meshes/F3.${MESH_EXT}" scale="${M_SCALE} ${M_SCALE} ${M_SCALE}"/>
						-->
        <box size="0.025 0.04 0.009"/>
      </geometry>
    </collision>
    <inertial>
      <mass value="0.01"/>
      <inertia ixx="0.001" ixy="0.0" ixz="0.0" iyy="0.001" iyz="0.0" izz="0.001"/>
    </inertial>
  </link>
  <gazebo reference="elbow_roll_f1__link">
    <material>Gazebo/WhiteEmissive</material>
    <selfCollide>false</selfCollide>
    <turnGravityOff>true</turnGravityOff>
  </gazebo>
  <link name="elbow_roll_servo">
    <visual>
      <origin rpy="0 0 1.57" xyz="0 0 0"/>
      <geometry>
        <mesh filename="package://robbie/meshes/ax12_box2.stl" scale="0.001 0.001 0.001"/>
      </geometry>
      <material name="ax12_color">
        <color rgba="0.1 0.1 0.1 1.0"/>
      </material>
    </visual>
    <collision>
      <origin rpy="0 0 1.57" xyz="0 0 0"/>
      <geometry>
        <box size="0.032 0.038 0.05"/>
        <!--
					<mesh filename="package://robbie/meshes/ax12_box2.${MESH_EXT}" scale="${M_SCALE} ${M_SCALE} ${M_SCALE}"/>
					-->
      </geometry>
    </collision>
    <inertial>
      <mass value="0.055"/>
      <inertia ixx="0.001" ixy="0.0" ixz="0.0" iyy="0.001" iyz="0.0" izz="0.001"/>
    </inertial>
  </link>
  <gazebo reference="elbow_roll_servo">
    <material>Gazebo/FlatBlack</material>
    <selfCollide>false</selfCollide>
    <turnGravityOff>true</turnGravityOff>
  </gazebo>
  <link name="elbow_roll_bracket_f3">
    <visual>
      <origin rpy="0 -1.57 0" xyz="0 0 0"/>
      <geometry>
        <mesh filename="package://robbie/meshes/F3.stl" scale="0.001 0.001 0.001"/>
      </geometry>
      <material name="bracket_color">
        <color rgba="0.9 0.9 0.9 1.0"/>
      </material>
    </visual>
    <collision>
      <origin rpy="0 -1.57 0" xyz="0 0 0"/>
      <geometry>
        <!--
          				<mesh filename="package://robbie/meshes/F3.${MESH_EXT}" scale="${M_SCALE} ${M_SCALE} ${M_SCALE}"/>
						-->
        <box size="0.025 0.04 0.009"/>
      </geometry>
    </collision>
    <inertial>
      <mass value="0.01"/>
      <inertia ixx="0.001" ixy="0.0" ixz="0.0" iyy="0.001" iyz="0.0" izz="0.001"/>
    </inertial>
  </link>
  <gazebo reference="elbow_roll_bracket_f3">
    <material>Gazebo/WhiteEmissive</material>
    <selfCollide>false</selfCollide>
    <turnGravityOff>true</turnGravityOff>
  </gazebo>
  <!-- wrist_tilt joint-->
  <link name="wrist_tilt_servo">
    <visual>
      <origin rpy="0 1.57 0" xyz="0 0 0"/>
      <geometry>
        <mesh filename="package://robbie/meshes/ax12_box2.stl" scale="0.001 0.001 0.001"/>
      </geometry>
      <material name="ax12_color">
        <color rgba="0.1 0.1 0.1 1.0"/>
      </material>
    </visual>
    <collision>
      <origin rpy="0 1.57 0" xyz="0 0 0"/>
      <geometry>
        <box size="0.032 0.038 0.05"/>
        <!--
					<mesh filename="package://robbie/meshes/ax12_box2.${MESH_EXT}" scale="${M_SCALE} ${M_SCALE} ${M_SCALE}"/>
					-->
      </geometry>
    </collision>
    <inertial>
      <mass value="0.055"/>
      <inertia ixx="0.001" ixy="0.0" ixz="0.0" iyy="0.001" iyz="0.0" izz="0.001"/>
    </inertial>
  </link>
  <gazebo reference="wrist_tilt_servo">
    <material>Gazebo/FlatBlack</material>
    <selfCollide>false</selfCollide>
    <turnGravityOff>true</turnGravityOff>
  </gazebo>
  <link name="wrist_tilt_bracket_f2">
    <visual>
      <origin rpy="0 1.57 0" xyz="0 0 0"/>
      <geometry>
        <mesh filename="package://robbie/meshes/F2.stl" scale="0.001 0.001 0.001"/>
      </geometry>
      <material name="bracket_color">
        <color rgba="0.9 0.9 0.9 1.0"/>
      </material>
    </visual>
    <collision>
      <origin rpy="0 1.57 0" xyz="0 0 0"/>
      <geometry>
        <box size="0.026 0.05 0.038"/>
        <!--
          				<mesh filename="package://robbie/meshes/F2.${MESH_EXT}" scale="${M_SCALE} ${M_SCALE} ${M_SCALE}"/>
          				-->
      </geometry>
    </collision>
    <inertial>
      <mass value="0.02"/>
      <inertia ixx="0.001" ixy="0.0" ixz="0.0" iyy="0.001" iyz="0.0" izz="0.001"/>
    </inertial>
  </link>
  <gazebo reference="wrist_tilt_bracket_f2">
    <material>Gazebo/WhiteEmissive</material>
    <selfCollide>false</selfCollide>
    <turnGravityOff>true</turnGravityOff>
  </gazebo>
  <link name="wrist_bracket_f2">
    <visual>
      <origin rpy="1.57 0 -1.57" xyz="0 0 0"/>
      <geometry>
        <mesh filename="package://robbie/meshes/F2.stl" scale="0.001 0.001 0.001"/>
      </geometry>
      <material name="bracket_color">
        <color rgba="0.9 0.9 0.9 1.0"/>
      </material>
    </visual>
    <collision>
      <origin rpy="1.57 0 -1.57" xyz="0 0 0"/>
      <geometry>
        <box size="0.026 0.05 0.038"/>
        <!--
          				<mesh filename="package://robbie/meshes/F2.${MESH_EXT}" scale="${M_SCALE} ${M_SCALE} ${M_SCALE}"/>
          				-->
      </geometry>
    </collision>
    <inertial>
      <mass value="0.02"/>
      <inertia ixx="0.001" ixy="0.0" ixz="0.0" iyy="0.001" iyz="0.0" izz="0.001"/>
    </inertial>
  </link>
  <gazebo reference="wrist_bracket_f2">
    <material>Gazebo/WhiteEmissive</material>
    <selfCollide>false</selfCollide>
    <turnGravityOff>true</turnGravityOff>
  </gazebo>
  <!-- wrist_pan_ joint-->
  <link name="wrist_pan_servo">
    <visual>
      <origin rpy="1.57 0 -1.57" xyz="0 0 0"/>
      <geometry>
        <mesh filename="package://robbie/meshes/ax12_box2.stl" scale="0.001 0.001 0.001"/>
      </geometry>
      <material name="ax12_color">
        <color rgba="0.1 0.1 0.1 1.0"/>
      </material>
    </visual>
    <collision>
      <origin rpy="1.57 0 -1.57" xyz="0 0 0"/>
      <geometry>
        <box size="0.032 0.038 0.05"/>
        <!--
					<mesh filename="package://robbie/meshes/ax12_box2.${MESH_EXT}" scale="${M_SCALE} ${M_SCALE} ${M_SCALE}"/>
					-->
      </geometry>
    </collision>
    <inertial>
      <mass value="0.055"/>
      <inertia ixx="0.001" ixy="0.0" ixz="0.0" iyy="0.001" iyz="0.0" izz="0.001"/>
    </inertial>
  </link>
  <gazebo reference="wrist_pan_servo">
    <material>Gazebo/FlatBlack</material>
    <selfCollide>false</selfCollide>
    <turnGravityOff>true</turnGravityOff>
  </gazebo>
  <link name="wrist_pan_servo_bracket_f3">
    <visual>
      <origin rpy="0 -1.57 0" xyz="0 0 0"/>
      <geometry>
        <mesh filename="package://robbie/meshes/F3.stl" scale="0.001 0.001 0.001"/>
      </geometry>
      <material name="bracket_color">
        <color rgba="0.9 0.9 0.9 1.0"/>
      </material>
    </visual>
    <collision>
      <origin rpy="0 -1.57 0" xyz="0 0 0"/>
      <geometry>
        <!--
          				<mesh filename="package://robbie/meshes/F3.${MESH_EXT}" scale="${M_SCALE} ${M_SCALE} ${M_SCALE}"/>
						-->
        <box size="0.025 0.04 0.009"/>
      </geometry>
    </collision>
    <inertial>
      <mass value="0.01"/>
      <inertia ixx="0.001" ixy="0.0" ixz="0.0" iyy="0.001" iyz="0.0" izz="0.001"/>
    </inertial>
  </link>
  <gazebo reference="wrist_pan_servo_bracket_f3">
    <material>Gazebo/WhiteEmissive</material>
    <selfCollide>false</selfCollide>
    <turnGravityOff>true</turnGravityOff>
  </gazebo>
  <link name="wrist_pan_servo_bracket2_f3">
    <visual>
      <origin rpy="0 -1.57 0" xyz="0 0 0"/>
      <geometry>
        <mesh filename="package://robbie/meshes/F3.stl" scale="0.001 0.001 0.001"/>
      </geometry>
      <material name="bracket_color">
        <color rgba="0.9 0.9 0.9 1.0"/>
      </material>
    </visual>
    <collision>
      <origin rpy="0 -1.57 0" xyz="0 0 0"/>
      <geometry>
        <!--
          				<mesh filename="package://robbie/meshes/F3.${MESH_EXT}" scale="${M_SCALE} ${M_SCALE} ${M_SCALE}"/>
						-->
        <box size="0.025 0.04 0.009"/>
      </geometry>
    </collision>
    <inertial>
      <mass value="0.01"/>
      <inertia ixx="0.001" ixy="0.0" ixz="0.0" iyy="0.001" iyz="0.0" izz="0.001"/>
    </inertial>
  </link>
  <gazebo reference="wrist_pan_servo_bracket2_f3">
    <material>Gazebo/WhiteEmissive</material>
    <selfCollide>false</selfCollide>
    <turnGravityOff>true</turnGravityOff>
  </gazebo>
  <!-- Gripper_joint-->
  <link name="gripper_servo">
    <visual>
      <origin rpy="0 1.57 0" xyz="0 0 0"/>
      <geometry>
        <mesh filename="package://robbie/meshes/ax12_box2.stl" scale="0.001 0.001 0.001"/>
      </geometry>
      <material name="ax12_color">
        <color rgba="0.1 0.1 0.1 1.0"/>
      </material>
    </visual>
    <collision>
      <origin rpy="0 1.57 0" xyz="0 0 0"/>
      <geometry>
        <box size="0.032 0.038 0.05"/>
        <!--
					<mesh filename="package://robbie/meshes/ax12_box2.${MESH_EXT}" scale="${M_SCALE} ${M_SCALE} ${M_SCALE}"/>
					-->
      </geometry>
    </collision>
    <inertial>
      <mass value="0.055"/>
      <inertia ixx="0.001" ixy="0.0" ixz="0.0" iyy="0.001" iyz="0.0" izz="0.001"/>
    </inertial>
  </link>
  <gazebo reference="gripper_servo">
    <material>Gazebo/FlatBlack</material>
    <selfCollide>false</selfCollide>
    <turnGravityOff>true</turnGravityOff>
  </gazebo>
  <link name="gripper_bracket_f2">
    <visual>
      <origin rpy="3.1415 0 0" xyz="0 0 0"/>
      <geometry>
        <mesh filename="package://robbie/meshes/F2.stl" scale="0.001 0.001 0.001"/>
      </geometry>
      <material name="bracket_color">
        <color rgba="0.9 0.9 0.9 1.0"/>
      </material>
    </visual>
    <collision>
      <origin rpy="3.1415 0 0" xyz="0 0 0"/>
      <geometry>
        <box size="0.026 0.05 0.038"/>
        <!--
          				<mesh filename="package://robbie/meshes/F2.${MESH_EXT}" scale="${M_SCALE} ${M_SCALE} ${M_SCALE}"/>
          				-->
      </geometry>
    </collision>
    <inertial>
      <mass value="0.02"/>
      <inertia ixx="0.001" ixy="0.0" ixz="0.0" iyy="0.001" iyz="0.0" izz="0.001"/>
    </inertial>
  </link>
  <gazebo reference="gripper_bracket_f2">
    <material>Gazebo/WhiteEmissive</material>
    <selfCollide>false</selfCollide>
    <turnGravityOff>true</turnGravityOff>
  </gazebo>
  <link name="right_finger_link">
    <visual>
      <origin rpy="1.57 0 0" xyz="0 0 0"/>
      <geometry>
        <box size="0.08 0.005 0.035"/>
      </geometry>
      <material name="grey3">
        <color rgba="0.8 0.8 0.8 1.0"/>
      </material>
    </visual>
    <collision>
      <origin rpy="1.57 0 0" xyz="0 0 0"/>
      <geometry>
        <box size="0.08 0.005 0.035"/>
      </geometry>
    </collision>
    <inertial>
      <mass value="0.1"/>
      <inertia ixx="0.001" ixy="0.0" ixz="0.0" iyy="0.001" iyz="0.0" izz="0.001"/>
    </inertial>
  </link>
  <gazebo reference="right_finger_link">
    <material>Gazebo/FlatBlack</material>
    <selfCollide>false</selfCollide>
    <turnGravityOff>true</turnGravityOff>
  </gazebo>
  <link name="left_finger_link">
    <visual>
      <origin rpy="0 0 0" xyz="0 0 0"/>
      <geometry>
        <box size="0.08 0.005 0.005"/>
      </geometry>
      <material name="grey3">
        <color rgba="0.8 0.8 0.8 1.0"/>
      </material>
    </visual>
    <collision>
      <origin rpy="0 0 0" xyz="0 0 0"/>
      <geometry>
        <box size="0.08 0.005 0.005"/>
      </geometry>
    </collision>
    <inertial>
      <mass value="0.1"/>
      <inertia ixx="0.001" ixy="0.0" ixz="0.0" iyy="0.001" iyz="0.0" izz="0.001"/>
    </inertial>
  </link>
  <gazebo reference="left_finger_link">
    <material>Gazebo/FlatBlack</material>
    <selfCollide>false</selfCollide>
    <turnGravityOff>true</turnGravityOff>
  </gazebo>
  <link name="torso_link">
    <visual>
      <origin rpy="0 0 0" xyz="0 0 0"/>
      <geometry>
        <cylinder length="0.2" radius="0.04"/>
      </geometry>
      <material name="blue1">
        <color rgba="0 0 0.9 1.0"/>
      </material>
    </visual>
    <collision>
      <origin rpy="0 0 0" xyz="0 0 0"/>
      <geometry>
        <cylinder length="0.2" radius="0.04"/>
      </geometry>
    </collision>
    <inertial>
      <mass value="0.25"/>
      <inertia ixx="0.001" ixy="0.0" ixz="0.0" iyy="0.001" iyz="0.0" izz="0.001"/>
    </inertial>
  </link>
  <gazebo reference="torso_link">
    <material>Gazebo/WhiteEmissive</material>
    <selfCollide>false</selfCollide>
    <turnGravityOff>true</turnGravityOff>
  </gazebo>
  <link name="head_pan_link">
    <visual>
      <origin rpy="1.57 0  1.57" xyz="0 0 0"/>
      <geometry>
        <mesh filename="package://robbie/meshes/ax12_box2.stl" scale="0.001 0.001 0.001"/>
      </geometry>
      <material name="ax12_color">
        <color rgba="0.1 0.1 0.1 1.0"/>
      </material>
    </visual>
    <collision>
      <origin rpy="1.57 0  1.57" xyz="0 0 0"/>
      <geometry>
        <box size="0.032 0.038 0.05"/>
        <!--
					<mesh filename="package://robbie/meshes/ax12_box2.${MESH_EXT}" scale="${M_SCALE} ${M_SCALE} ${M_SCALE}"/>
					-->
      </geometry>
    </collision>
    <inertial>
      <mass value="0.055"/>
      <inertia ixx="0.001" ixy="0.0" ixz="0.0" iyy="0.001" iyz="0.0" izz="0.001"/>
    </inertial>
  </link>
  <gazebo reference="head_pan_link">
    <material>Gazebo/FlatBlack</material>
    <selfCollide>false</selfCollide>
    <turnGravityOff>true</turnGravityOff>
  </gazebo>
  <link name="pan_tilt_bracket">
    <visual>
      <origin rpy="0 3.1415 0" xyz="0 0 0"/>
      <geometry>
        <mesh filename="package://robbie/meshes/F2.stl" scale="0.001 0.001 0.001"/>
      </geometry>
      <material name="bracket_color">
        <color rgba="0.9 0.9 0.9 1.0"/>
      </material>
    </visual>
    <collision>
      <origin rpy="0 3.1415 0" xyz="0 0 0"/>
      <geometry>
        <box size="0.026 0.05 0.038"/>
        <!--
          				<mesh filename="package://robbie/meshes/F2.${MESH_EXT}" scale="${M_SCALE} ${M_SCALE} ${M_SCALE}"/>
          				-->
      </geometry>
    </collision>
    <inertial>
      <mass value="0.02"/>
      <inertia ixx="0.001" ixy="0.0" ixz="0.0" iyy="0.001" iyz="0.0" izz="0.001"/>
    </inertial>
  </link>
  <gazebo reference="pan_tilt_bracket">
    <material>Gazebo/WhiteEmissive</material>
    <selfCollide>false</selfCollide>
    <turnGravityOff>true</turnGravityOff>
  </gazebo>
  <link name="head_tilt_link">
    <visual>
      <origin rpy="3.1415 0 0" xyz="0 0 0"/>
      <geometry>
        <mesh filename="package://robbie/meshes/ax12_box2.stl" scale="0.001 0.001 0.001"/>
      </geometry>
      <material name="ax12_color">
        <color rgba="0.1 0.1 0.1 1.0"/>
      </material>
    </visual>
    <collision>
      <origin rpy="3.1415 0 0" xyz="0 0 0"/>
      <geometry>
        <box size="0.032 0.038 0.05"/>
        <!--
					<mesh filename="package://robbie/meshes/ax12_box2.${MESH_EXT}" scale="${M_SCALE} ${M_SCALE} ${M_SCALE}"/>
					-->
      </geometry>
    </collision>
    <inertial>
      <mass value="0.055"/>
      <inertia ixx="0.001" ixy="0.0" ixz="0.0" iyy="0.001" iyz="0.0" izz="0.001"/>
    </inertial>
  </link>
  <gazebo reference="head_tilt_link">
    <material>Gazebo/FlatBlack</material>
    <selfCollide>false</selfCollide>
    <turnGravityOff>true</turnGravityOff>
  </gazebo>
  <link name="neck_link">
    <visual>
      <origin rpy="0 0 0" xyz="0 0 0"/>
      <geometry>
        <mesh filename="package://robbie/meshes/F3.stl" scale="0.001 0.001 0.001"/>
      </geometry>
      <material name="bracket_color">
        <color rgba="0.9 0.9 0.9 1.0"/>
      </material>
    </visual>
    <collision>
      <origin rpy="0 0 0" xyz="0 0 0"/>
      <geometry>
        <!--
          				<mesh filename="package://robbie/meshes/F3.${MESH_EXT}" scale="${M_SCALE} ${M_SCALE} ${M_SCALE}"/>
						-->
        <box size="0.025 0.04 0.009"/>
      </geometry>
    </collision>
    <inertial>
      <mass value="0.01"/>
      <inertia ixx="0.001" ixy="0.0" ixz="0.0" iyy="0.001" iyz="0.0" izz="0.001"/>
    </inertial>
  </link>
  <gazebo reference="neck_link">
    <material>Gazebo/WhiteEmissive</material>
    <selfCollide>false</selfCollide>
    <turnGravityOff>true</turnGravityOff>
  </gazebo>
  <link name="head_base_link">
    <visual>
      <origin rpy="0 0 0" xyz="0 0 0"/>
      <geometry>
        <box size="0.06 0.08 0.005"/>
      </geometry>
      <material name="black">
        <color rgba="0.1 0.1 0.1 1.0"/>
      </material>
    </visual>
    <collision>
      <origin rpy="0 0 0" xyz="0 0 0"/>
      <geometry>
        <box size="0.06 0.08 0.005"/>
      </geometry>
    </collision>
    <inertial>
      <mass value="0.1"/>
      <inertia ixx="0.001" ixy="0.0" ixz="0.0" iyy="0.001" iyz="0.0" izz="0.001"/>
    </inertial>
  </link>
  <gazebo reference="head_base_link">
    <material>Gazebo/FlatBlack</material>
    <selfCollide>false</selfCollide>
    <turnGravityOff>true</turnGravityOff>
  </gazebo>
  <link name="kinect_link">
    <inertial>
      <mass value="1.0"/>
      <origin xyz="0 0 0"/>
      <inertia ixx="1.0" ixy="0.0" ixz="0.0" iyy="1.0" iyz="0.0" izz="1.0"/>
    </inertial>
    <visual>
      <origin rpy="0 0 0" xyz=" 0 0 0 "/>
      <geometry>
        <mesh filename="package://robbie/meshes/kinect.dae"/>
      </geometry>
    </visual>
    <collision>
      <origin rpy="0 0 0" xyz="0 0 0"/>
      <geometry>
        <mesh filename="package://robbie/meshes/kinect.dae"/>
      </geometry>
    </collision>
  </link>
  <!-- =================== Joint Definitions ==================== -->
  <joint name="base_link_joint" type="fixed">
    <parent link="base_link"/>
    <child link="deck_link"/>
    <origin rpy="0 0 0" xyz="0 0 .33"/>
  </joint>
  <joint name="r_wheel_joint" type="fixed">
    <parent link="base_link"/>
    <child link="r_wheel_link"/>
    <origin rpy="0 0 0" xyz="0.15 0.2 0.075"/>
  </joint>
  <joint name="l_wheel_joint" type="fixed">
    <parent link="base_link"/>
    <child link="l_wheel_link"/>
    <origin rpy="0 0 0" xyz="0.15 -0.2 0.075"/>
  </joint>
  <joint name="arm_tilt_servo" type="fixed">
    <parent link="deck_link"/>
    <child link="arm_shoulder_tilt_link"/>
    <origin rpy="0 0 0" xyz="0.165 0 .045"/>
    <axis xyz="0 0 1"/>
    <limit effort="10" lower="-3.1416" upper="3.1416" velocity="0"/>
    <dynamics damping="0.0"/>
  </joint>
  <!-- arm_pan_joint-->
  <joint name="arm_pan_joint" type="revolute">
    <parent link="arm_shoulder_tilt_link"/>
    <child link="arm_tilt_f3"/>
    <origin rpy="0 0 0" xyz="0 0 0.01"/>
    <axis xyz="0 0 1"/>
    <limit effort="10" lower="-1.57" upper="1.57" velocity="0"/>
  </joint>
  <joint name="arm_tilt1_joint" type="fixed">
    <parent link="arm_tilt_f3"/>
    <child link="arm_tilt_servo"/>
    <origin rpy="0 0 0" xyz="0.0 0.01 0.035"/>
    <axis xyz="0 0 0"/>
    <limit effort="10" lower="-1.57" upper="1.57" velocity="0"/>
    <dynamics damping="0.0"/>
  </joint>
  <!-- arm_tilt_joint-->
  <joint name="arm_tilt_joint" type="revolute">
    <parent link="arm_tilt_servo"/>
    <child link="arm_extension_f3"/>
    <origin rpy="0 0 0" xyz="0 -0.015 0.0"/>
    <axis xyz="0 -1 0"/>
    <limit effort="10" lower="-1.57" upper="1.57" velocity="0"/>
    <dynamics damping="0.0"/>
  </joint>
  <joint name="arm_extension_1_link" type="fixed">
    <parent link="arm_extension_f3"/>
    <child link="arm_extension_1"/>
    <origin rpy="0 0 0" xyz="0.1 -0.019 0.0"/>
  </joint>
  <joint name="arm_extension_1" type="fixed">
    <parent link="arm_extension_1"/>
    <child link="elbow_bracket_f3"/>
    <origin rpy="0 0 0" xyz="0.1 0 0.01"/>
  </joint>
  <joint name="elbow_tilt_servo" type="fixed">
    <parent link="elbow_bracket_f3"/>
    <child link="elbow_tilt_servo"/>
    <origin rpy="0 0 0" xyz="0.03 0 0.01"/>
  </joint>
  <!-- elbow_tilt_joint-->
  <joint name="elbow_tilt_joint" type="revolute">
    <parent link="elbow_tilt_servo"/>
    <child link="elbow_bracket_f2"/>
    <origin rpy="0 0 0" xyz="0.0 0 0.0"/>
    <axis xyz="0 1 0"/>
    <limit effort="10" lower="-1.57" upper="1.57" velocity="0"/>
    <dynamics damping="0.0"/>
  </joint>
  <!-- elbow roll fwd bracket-->
  <joint name="elbow_roll_f1_bracket" type="fixed">
    <parent link="elbow_bracket_f2"/>
    <child link="arm_extension_2"/>
    <origin rpy="0 0 0" xyz="0.135 0 0.0"/>
  </joint>
  <joint name="elbow_extension_bracket" type="fixed">
    <parent link="arm_extension_2"/>
    <child link="elbow_roll_f1__link"/>
    <origin rpy="0 0 0" xyz="0.1 0 0.01"/>
  </joint>
  <joint name="elbow_roll_servo" type="fixed">
    <parent link="elbow_roll_f1__link"/>
    <child link="elbow_roll_servo"/>
    <origin rpy="0 0 0" xyz="0 0 0.04"/>
  </joint>
  <!-- elbow_roll joint-->
  <joint name="elbow_roll_joint" type="revolute">
    <parent link="elbow_roll_servo"/>
    <child link="elbow_roll_bracket_f3"/>
    <origin rpy="0 0 0" xyz="0.02 0 0.0"/>
    <axis xyz="1 0 0"/>
    <limit effort="10" lower="-3.1416" upper="3.1416" velocity="0"/>
    <dynamics damping="0.0"/>
  </joint>
  <joint name="wrist_tilt_bracket" type="fixed">
    <parent link="elbow_roll_bracket_f3"/>
    <child link="wrist_tilt_servo"/>
    <origin rpy="0 0 0" xyz="0.04 0 0.0"/>
    <axis xyz="1 0 0"/>
    <limit effort="10" lower="-3.1416" upper="3.1416" velocity="0"/>
    <dynamics damping="0.0"/>
  </joint>
  <!--wrist_tilt_joint-->
  <joint name="wrist_tilt_joint" type="revolute">
    <parent link="wrist_tilt_servo"/>
    <child link="wrist_tilt_bracket_f2"/>
    <origin rpy="0 0 0" xyz="0 0 0.0"/>
    <axis xyz="0 1 0"/>
    <limit effort="10" lower="-1.57" upper="1.57" velocity="0"/>
    <dynamics damping="0.0"/>
  </joint>
  <joint name="wrist_joint" type="fixed">
    <parent link="wrist_tilt_bracket_f2"/>
    <child link="wrist_bracket_f2"/>
    <origin rpy="0 0 0" xyz="0.05 0 0.0"/>
    <axis xyz="0 1 0"/>
    <limit effort="10" lower="-1.57" upper="1.57" velocity="0"/>
    <dynamics damping="0.0"/>
  </joint>
  <!--wrist_pan_joint-->
  <joint name="wrist_pan_joint" type="revolute">
    <parent link="wrist_bracket_f2"/>
    <child link="wrist_pan_servo"/>
    <origin rpy="0 0 0" xyz="0.0 0 0.0"/>
    <axis xyz="0 0 1"/>
    <limit effort="10" lower="-1.57" upper="1.57" velocity="0"/>
    <dynamics damping="0.0"/>
  </joint>
  <joint name="wrist_pan_bracket" type="fixed">
    <parent link="wrist_pan_servo"/>
    <child link="wrist_pan_servo_bracket_f3"/>
    <origin rpy="0 0 0" xyz="0.035 0 0.0"/>
  </joint>
  <joint name="gripper_bracket" type="fixed">
    <parent link="wrist_pan_servo_bracket_f3"/>
    <child link="wrist_pan_servo_bracket2_f3"/>
    <origin rpy="0 0 0" xyz="0.02 0 0.0"/>
  </joint>
  <joint name="gripper_servo" type="fixed">
    <parent link="wrist_pan_servo_bracket2_f3"/>
    <child link="gripper_servo"/>
    <origin rpy="0 0 0" xyz="0.04 0 0.0"/>
  </joint>
  <!-- gripper_joint-->
  <joint name="gripper_joint" type="revolute">
    <parent link="gripper_servo"/>
    <child link="gripper_bracket_f2"/>
    <origin rpy="0 0 0" xyz="0 0.0 0.0"/>
    <axis xyz="0 1 0"/>
    <limit effort="10" lower="-0.98" upper="0.15" velocity="0"/>
    <dynamics damping="0.0"/>
  </joint>
  <joint name="finger_link_l" type="fixed">
    <parent link="gripper_servo"/>
    <child link="left_finger_link"/>
    <origin rpy="0 0 0" xyz="0.035 0.0 0.01"/>
  </joint>
  <joint name="finger_link_r" type="fixed">
    <parent link="gripper_bracket_f2"/>
    <child link="right_finger_link"/>
    <origin rpy="0 0 0" xyz="0.035 -0.0 -0.025"/>
  </joint>
  <joint name="torso_joint" type="fixed">
    <parent link="deck_link"/>
    <child link="torso_link"/>
    <origin rpy="0 0 0" xyz="-0.13 0 0.15"/>
  </joint>
  <joint name="head_pan_servo" type="fixed">
    <parent link="torso_link"/>
    <child link="head_pan_link"/>
    <origin rpy="0 0 0" xyz="0 0 0.13"/>
  </joint>
  <!-- head_pan_joint-->
  <joint name="head_pan_joint" type="revolute">
    <parent link="head_pan_link"/>
    <child link="pan_tilt_bracket"/>
    <origin rpy="0 0 0" xyz="0.01 0 0.04"/>
    <origin rpy="0 0 0" xyz="0 0 0.0"/>
    <axis xyz="0 0 1"/>
    <limit effort="10" lower="-3.1416" upper="3.1416" velocity="0"/>
    <dynamics damping="0.0"/>
  </joint>
  <joint name="head_tilt_joint" type="revolute">
    <parent link="pan_tilt_bracket"/>
    <child link="head_tilt_link"/>
    <origin rpy="0 0 0" xyz="0 0 0.0"/>
    <axis xyz="0 -1 0"/>
    <limit effort="10" lower="-3.1416" upper="3.1416" velocity="0"/>
    <dynamics damping="0.0"/>
  </joint>
  <joint name="head_tilt_bracket" type="fixed">
    <parent link="head_tilt_link"/>
    <child link="neck_link"/>
    <origin rpy="0 0 0" xyz="0 0 0.045"/>
    <axis xyz="0 -1 0"/>
    <limit effort="10" lower="-1.57" upper="1.57" velocity="0"/>
    <dynamics damping="0.0"/>
  </joint>
  <joint name="neck_joint" type="fixed">
    <parent link="neck_link"/>
    <child link="head_base_link"/>
    <origin rpy="0 0 0" xyz="0 0 0.0"/>
  </joint>
  <joint name="head_joint" type="fixed">
    <parent link="head_base_link"/>
    <child link="kinect_link"/>
    <origin rpy="0 0 0" xyz="0.03 0 0.05"/>
  </joint>
  <joint name="kinect_depth_joint" type="fixed">
    <origin rpy="0 0 0" xyz="0 0.018 0"/>
    <parent link="kinect_link"/>
    <child link="openni_depth_frame"/>
  </joint>
  <link name="openni_depth_frame">
    <inertial>
      <mass value="0.0001"/>
      <origin xyz="0 0 0"/>
      <inertia ixx="0.0001" ixy="0.0" ixz="0.0" iyy="0.0001" iyz="0.0" izz="0.0001"/>
    </inertial>
  </link>
  <joint name="kinect_depth_optical_joint" type="fixed">
    <origin rpy="-1.570795 0 -1.570795" xyz="0 0 0"/>
    <parent link="openni_depth_frame"/>
    <child link="openni_depth_optical_frame"/>
  </joint>
  <link name="openni_depth_optical_frame">
    <inertial>
      <mass value="0.0001"/>
      <origin xyz="0 0 0"/>
      <inertia ixx="0.0001" ixy="0.0" ixz="0.0" iyy="0.0001" iyz="0.0" izz="0.0001"/>
    </inertial>
  </link>
  <joint name="kinect_rgb_joint" type="fixed">
    <origin rpy="0 0 0" xyz="0 -0.005 0"/>
    <parent link="kinect_link"/>
    <child link="openni_rgb_frame"/>
  </joint>
  <link name="openni_rgb_frame">
    <inertial>
      <mass value="0.0001"/>
      <origin xyz="0 0 0"/>
      <inertia ixx="0.0001" ixy="0.0" ixz="0.0" iyy="0.0001" iyz="0.0" izz="0.0001"/>
    </inertial>
  </link>
  <joint name="kinect_rgb_optical_joint" type="fixed">
    <origin rpy="-1.570795 0 -1.570795" xyz="0 0 0"/>
    <parent link="openni_rgb_frame"/>
    <child link="openni_rgb_optical_frame"/>
  </joint>
  <link name="openni_rgb_optical_frame">
    <inertial>
      <mass value="0.0001"/>
      <origin xyz="0 0 0"/>
      <inertia ixx="0.0001" ixy="0.0" ixz="0.0" iyy="0.0001" iyz="0.0" izz="0.0001"/>
    </inertial>
  </link>
  <gazebo reference="robbie">
  	</gazebo>
</robot>

