<?xml version="1.0" ?>
<!-- =================================================================================== -->
<!-- |    This document was autogenerated by xacro from robbie5.xacro                  | -->
<!-- |    EDITING THIS FILE BY HAND IS NOT RECOMMENDED                                 | -->
<!-- =================================================================================== -->
<!-- XML namespaces -->
<robot name="robbie" xmlns:controller="http://playerstage.sourceforge.net/gazebo/xmlschema/#controller" xmlns:interface="http://playerstage.sourceforge.net/gazebo/xmlschema/#interface" xmlns:sensor="http://playerstage.sourceforge.net/gazebo/xmlschema/#sensor" xmlns:xacro="http://ros.org/wiki/xacro">
  <!-- ============================  A Few Color Macros  ============================ -->
  <!-- ============================   A Few Shape Macros  ============================ -->
  <!-- ============================   Link Definitions  ============================ -->
  <link name="base_link">
    <visual>
      <origin rpy="0 0 0" xyz="0 0 .135"/>
      <geometry>
        <box size="0.41 0.35 0.06"/>
      </geometry>
      <material name="green1">
        <color rgba="0 1 0 1.0"/>
      </material>
    </visual>
    <collision>
      <origin rpy="0 0 0" xyz="0 0 .135"/>
      <geometry>
        <box size="0.41 0.35 0.06"/>
      </geometry>
    </collision>
  </link>
  <gazebo reference="base_link">
    <material>Gazebo/FlatBlack</material>
    <selfCollide>false</selfCollide>
    <turnGravityOff>true</turnGravityOff>
  </gazebo>
  <link name="left_wheel">
    <visual>
      <origin rpy="1.57 0 0" xyz="0 0 0"/>
      <geometry>
        <cylinder length="0.035" radius="0.1025"/>
      </geometry>
      <material name="grey1">
        <color rgba="0.75 0.75 0.75 1.0"/>
      </material>
    </visual>
    <collision>
      <origin rpy="1.57 0 0" xyz="0 0 0"/>
      <geometry>
        <cylinder length="0.035" radius="0.1025"/>
      </geometry>
    </collision>
    <inertial>
      <mass value="0.1"/>
      <inertia ixx="0.001" ixy="0.0" ixz="0.0" iyy="0.001" iyz="0.0" izz="0.001"/>
    </inertial>
  </link>
  <gazebo reference="left_wheel">
    <material>Gazebo/Grey</material>
    <selfCollide>false</selfCollide>
    <turnGravityOff>true</turnGravityOff>
  </gazebo>
  <link name="right_wheel">
    <visual>
      <origin rpy="1.57 0 0" xyz="0 0 0"/>
      <geometry>
        <cylinder length="0.035" radius="0.1025"/>
      </geometry>
      <material name="grey1">
        <color rgba="0.75 0.75 0.75 1.0"/>
      </material>
    </visual>
    <collision>
      <origin rpy="1.57 0 0" xyz="0 0 0"/>
      <geometry>
        <cylinder length="0.035" radius="0.1025"/>
      </geometry>
    </collision>
    <inertial>
      <mass value="0.1"/>
      <inertia ixx="0.001" ixy="0.0" ixz="0.0" iyy="0.001" iyz="0.0" izz="0.001"/>
    </inertial>
  </link>
  <gazebo reference="right_wheel">
    <material>Gazebo/Grey</material>
    <selfCollide>false</selfCollide>
    <turnGravityOff>true</turnGravityOff>
  </gazebo>
  <link name="castor_wheel_l">
    <visual>
      <origin rpy="1.57 0 0" xyz="0 0 0"/>
      <geometry>
        <cylinder length="0.035" radius="0.04"/>
      </geometry>
      <material name="grey1">
        <color rgba="0.75 0.75 0.75 1.0"/>
      </material>
    </visual>
    <collision>
      <origin rpy="1.57 0 0" xyz="0 0 0"/>
      <geometry>
        <cylinder length="0.035" radius="0.04"/>
      </geometry>
    </collision>
    <inertial>
      <mass value="0.1"/>
      <inertia ixx="0.001" ixy="0.0" ixz="0.0" iyy="0.001" iyz="0.0" izz="0.001"/>
    </inertial>
  </link>
  <gazebo reference="castor_wheel_l">
    <material>Gazebo/Grey</material>
    <selfCollide>false</selfCollide>
    <turnGravityOff>true</turnGravityOff>
  </gazebo>
  <link name="castor_wheel_r">
    <visual>
      <origin rpy="1.57 0 0" xyz="0 0 0"/>
      <geometry>
        <cylinder length="0.035" radius="0.04"/>
      </geometry>
      <material name="grey1">
        <color rgba="0.75 0.75 0.75 1.0"/>
      </material>
    </visual>
    <collision>
      <origin rpy="1.57 0 0" xyz="0 0 0"/>
      <geometry>
        <cylinder length="0.035" radius="0.04"/>
      </geometry>
    </collision>
    <inertial>
      <mass value="0.1"/>
      <inertia ixx="0.001" ixy="0.0" ixz="0.0" iyy="0.001" iyz="0.0" izz="0.001"/>
    </inertial>
  </link>
  <gazebo reference="castor_wheel_r">
    <material>Gazebo/Grey</material>
    <selfCollide>false</selfCollide>
    <turnGravityOff>true</turnGravityOff>
  </gazebo>
  <link name="deck_link">
    <visual>
      <origin rpy="0 0 0" xyz="0.1 0 0"/>
      <geometry>
        <cylinder length="0.52" radius="0.175"/>
      </geometry>
      <material name="black">
        <color rgba="0.1 0.1 0.1 1.0"/>
      </material>
    </visual>
    <collision>
      <origin rpy="0 0 0" xyz="0.1 0 0"/>
      <geometry>
        <cylinder length="0.52" radius="0.175"/>
      </geometry>
    </collision>
    <inertial>
      <mass value="0.2"/>
      <inertia ixx="0.001" ixy="0.0" ixz="0.0" iyy="0.001" iyz="0.0" izz="0.001"/>
    </inertial>
  </link>
  <gazebo reference="deck_link">
    <material>Gazebo/grey</material>
    <selfCollide>false</selfCollide>
    <turnGravityOff>true</turnGravityOff>
  </gazebo>
  <link name="imu_link">
    <visual>
      <origin rpy="0 0 0" xyz="0 0 .15"/>
      <geometry>
        <box size="0.045 0.065 0.01"/>
      </geometry>
      <material name="black">
        <color rgba="0.1 0.1 0.1 1.0"/>
      </material>
    </visual>
    <collision>
      <origin rpy="0 0 0" xyz="0 0 .15"/>
      <geometry>
        <box size="0.045 0.065 0.01"/>
      </geometry>
    </collision>
  </link>
  <gazebo reference="imu_link">
    <material>Gazebo/FlatBlack</material>
    <selfCollide>false</selfCollide>
    <turnGravityOff>true</turnGravityOff>
  </gazebo>
  <link name="torso_link">
    <visual>
      <origin rpy="0 0 0" xyz="0 0 0"/>
      <geometry>
        <cylinder length="0.48" radius="0.03"/>
      </geometry>
      <material name="blue1">
        <color rgba="0 0 0.9 1.0"/>
      </material>
    </visual>
    <collision>
      <origin rpy="0 0 0" xyz="0 0 0"/>
      <geometry>
        <cylinder length="0.48" radius="0.03"/>
      </geometry>
    </collision>
    <inertial>
      <mass value="0.25"/>
      <inertia ixx="0.001" ixy="0.0" ixz="0.0" iyy="0.001" iyz="0.0" izz="0.001"/>
    </inertial>
  </link>
  <gazebo reference="torso_link">
    <material>Gazebo/WhiteEmissive</material>
    <selfCollide>false</selfCollide>
    <turnGravityOff>true</turnGravityOff>
  </gazebo>
  <!--<xacro:my_box name="chest_link" lwh="0.1 0.24 0.16" xyz="0 0 0" rpy="0 0 0" mass="0.1" material="Gazebo/FlatBlack">
		<xacro:blue1 />
	</xacro:my_box>-->
  <!--##################right arm links##########################################################################-->
  <link name="right_arm_tilt_link">
    <visual>
      <geometry>
        <mesh filename="package://robbie/meshes/Right_tilt_bracket_new.stl" scale="0.001 0.001 0.001"/>
      </geometry>
      <material name="green">
        <color rgba="0.1 0.8 0 0.8"/>
      </material>
      <origin rpy="0 0 0" xyz="0 0 -0.07"/>
    </visual>
  </link>
  <link name="right_lift_link">
    <visual>
      <geometry>
        <mesh filename="package://robbie/meshes/Right_shoulder_lift.stl" scale="0.001 0.001 0.001"/>
      </geometry>
      <material name="yellow2">
        <color rgba="0.8 0.8 0 1.0"/>
      </material>
      <origin rpy="0 1.57 1.57" xyz="0 0 0"/>
      <!--<origin rpy="0 1.57 0" xyz="0 0 0"/>-->
    </visual>
  </link>
  <link name="right_rotate_link">
    <visual>
      <geometry>
        <mesh filename="package://robbie/meshes/Right_gearbox.stl" scale="0.001 0.001 0.001"/>
      </geometry>
      <material name="yellow2">
        <color rgba="0.8 0.8 0 1.0"/>
      </material>
      <origin rpy="1.57 3.14 0" xyz="0 0 0"/>
    </visual>
  </link>
  <link name="right_elbow_link">
    <visual>
      <geometry>
        <mesh filename="package://robbie/meshes/Right_bicep_frame.stl" scale="0.001 0.001 0.001"/>
      </geometry>
      <material name="green">
        <color rgba="0.1 0.8 0 0.8"/>
      </material>
      <origin rpy="3.14 0 0" xyz="0 0 -0.025"/>
    </visual>
  </link>
  <link name="right_forearm_link">
    <visual>
      <geometry>
        <mesh filename="package://robbie/meshes/Right_foreArm.stl" scale="0.001 0.001 0.001"/>
      </geometry>
      <material name="green">
        <color rgba="0.1 0.8 0 1"/>
      </material>
      <origin rpy="0 1.57 0" xyz="0.12 0 0"/>
    </visual>
  </link>
  <link name="shoulder_bracket_link">
    <visual>
      <geometry>
        <mesh filename="package://robbie/meshes/shoulder_bracket.stl" scale="0.001 0.001 0.001"/>
      </geometry>
      <material name="green">
        <color rgba="0.1 0.8 0 0.8"/>
      </material>
      <origin rpy="0 3.14 3.14" xyz="0.06 0 -0.015"/>
    </visual>
  </link>
  <!-- wrist_pan_ joint-->
  <link name="wrist_pan_servo">
    <visual>
      <origin rpy="0 0 0" xyz="0 0 0"/>
      <geometry>
        <mesh filename="package://robbie/meshes/ax12_box2.stl" scale="0.001 0.001 0.001"/>
      </geometry>
      <material name="ax12_color">
        <color rgba="0.1 0.1 0.1 1.0"/>
      </material>
    </visual>
    <collision>
      <origin rpy="0 0 0" xyz="0 0 0"/>
      <geometry>
        <!--<box size="0.032 0.038 0.05" />-->
        <mesh filename="package://robbie/meshes/ax12_box2.stl" scale="0.001 0.001 0.001"/>
      </geometry>
    </collision>
    <inertial>
      <mass value="0.055"/>
      <inertia ixx="0.001" ixy="0.0" ixz="0.0" iyy="0.001" iyz="0.0" izz="0.001"/>
    </inertial>
  </link>
  <gazebo reference="wrist_pan_servo">
    <material>Gazebo/FlatBlack</material>
    <selfCollide>false</selfCollide>
    <turnGravityOff>true</turnGravityOff>
  </gazebo>
  <link name="wrist_pan_servo_bracket_f3">
    <visual>
      <origin rpy="1.57 0 0" xyz="0 0.005 0"/>
      <geometry>
        <mesh filename="package://robbie/meshes/F3.stl" scale="0.001 0.001 0.001"/>
      </geometry>
      <material name="grey1">
        <color rgba="0.75 0.75 0.75 1.0"/>
      </material>
      <material name="bracket_color">
        <color rgba="0.9 0.9 0.9 1.0"/>
      </material>
    </visual>
    <collision>
      <origin rpy="1.57 0 0" xyz="0 0.005 0"/>
      <geometry>
        <mesh filename="package://robbie/meshes/F3.stl" scale="0.001 0.001 0.001"/>
      </geometry>
    </collision>
    <inertial>
      <mass value="0.01"/>
      <inertia ixx="0.001" ixy="0.0" ixz="0.0" iyy="0.001" iyz="0.0" izz="0.001"/>
    </inertial>
  </link>
  <gazebo reference="wrist_pan_servo_bracket_f3">
    <material>Gazebo/WhiteEmissive</material>
    <selfCollide>false</selfCollide>
    <turnGravityOff>true</turnGravityOff>
  </gazebo>
  <!-- <xacro:F3_bracket name="wrist_pan_servo_bracket2_f3" xyz="0 0 0" rpy="0 -1.57 0" />-->
  <!-- wrist_tilt joint-->
  <link name="wrist_tilt_servo">
    <visual>
      <origin rpy="-1.57 0 0" xyz="-0.04 0.05 0"/>
      <geometry>
        <mesh filename="package://robbie/meshes/ax12_box2.stl" scale="0.001 0.001 0.001"/>
      </geometry>
      <material name="ax12_color">
        <color rgba="0.1 0.1 0.1 1.0"/>
      </material>
    </visual>
    <collision>
      <origin rpy="-1.57 0 0" xyz="-0.04 0.05 0"/>
      <geometry>
        <!--<box size="0.032 0.038 0.05" />-->
        <mesh filename="package://robbie/meshes/ax12_box2.stl" scale="0.001 0.001 0.001"/>
      </geometry>
    </collision>
    <inertial>
      <mass value="0.055"/>
      <inertia ixx="0.001" ixy="0.0" ixz="0.0" iyy="0.001" iyz="0.0" izz="0.001"/>
    </inertial>
  </link>
  <gazebo reference="wrist_tilt_servo">
    <material>Gazebo/FlatBlack</material>
    <selfCollide>false</selfCollide>
    <turnGravityOff>true</turnGravityOff>
  </gazebo>
  <link name="wrist_tilt_bracket_f2">
    <visual>
      <origin rpy="-1.57 0 0" xyz="0 0 0"/>
      <geometry>
        <mesh filename="package://robbie/meshes/F2.stl" scale="0.001 0.001 0.001"/>
      </geometry>
      <material name="bracket_color">
        <color rgba="0.9 0.9 0.9 1.0"/>
      </material>
    </visual>
    <collision>
      <origin rpy="-1.57 0 0" xyz="0 0 0"/>
      <geometry>
        <mesh filename="package://robbie/meshes/F2.stl" scale="0.001 0.001 0.001"/>
      </geometry>
    </collision>
    <inertial>
      <mass value="0.02"/>
      <inertia ixx="0.001" ixy="0.0" ixz="0.0" iyy="0.001" iyz="0.0" izz="0.001"/>
    </inertial>
  </link>
  <gazebo reference="wrist_tilt_bracket_f2">
    <material>Gazebo/WhiteEmissive</material>
    <selfCollide>false</selfCollide>
    <turnGravityOff>true</turnGravityOff>
  </gazebo>
  <link name="gripper_bracket_f3">
    <visual>
      <origin rpy="1.57 1.57 0" xyz="0 0 0"/>
      <geometry>
        <mesh filename="package://robbie/meshes/F3.stl" scale="0.001 0.001 0.001"/>
      </geometry>
      <material name="grey1">
        <color rgba="0.75 0.75 0.75 1.0"/>
      </material>
      <material name="bracket_color">
        <color rgba="0.9 0.9 0.9 1.0"/>
      </material>
    </visual>
    <collision>
      <origin rpy="1.57 1.57 0" xyz="0 0 0"/>
      <geometry>
        <mesh filename="package://robbie/meshes/F3.stl" scale="0.001 0.001 0.001"/>
      </geometry>
    </collision>
    <inertial>
      <mass value="0.01"/>
      <inertia ixx="0.001" ixy="0.0" ixz="0.0" iyy="0.001" iyz="0.0" izz="0.001"/>
    </inertial>
  </link>
  <gazebo reference="gripper_bracket_f3">
    <material>Gazebo/WhiteEmissive</material>
    <selfCollide>false</selfCollide>
    <turnGravityOff>true</turnGravityOff>
  </gazebo>
  <!-- Gripper_joint-->
  <link name="gripper_servo">
    <visual>
      <origin rpy="0 0 -1.57" xyz="0 0 0"/>
      <geometry>
        <mesh filename="package://robbie/meshes/ax12_box2.stl" scale="0.001 0.001 0.001"/>
      </geometry>
      <material name="ax12_color">
        <color rgba="0.1 0.1 0.1 1.0"/>
      </material>
    </visual>
    <collision>
      <origin rpy="0 0 -1.57" xyz="0 0 0"/>
      <geometry>
        <!--<box size="0.032 0.038 0.05" />-->
        <mesh filename="package://robbie/meshes/ax12_box2.stl" scale="0.001 0.001 0.001"/>
      </geometry>
    </collision>
    <inertial>
      <mass value="0.055"/>
      <inertia ixx="0.001" ixy="0.0" ixz="0.0" iyy="0.001" iyz="0.0" izz="0.001"/>
    </inertial>
  </link>
  <gazebo reference="gripper_servo">
    <material>Gazebo/FlatBlack</material>
    <selfCollide>false</selfCollide>
    <turnGravityOff>true</turnGravityOff>
  </gazebo>
  <link name="gripper_bracket_f2">
    <visual>
      <origin rpy="0 0 1.57" xyz="0 0 0"/>
      <geometry>
        <mesh filename="package://robbie/meshes/F2.stl" scale="0.001 0.001 0.001"/>
      </geometry>
      <material name="bracket_color">
        <color rgba="0.9 0.9 0.9 1.0"/>
      </material>
    </visual>
    <collision>
      <origin rpy="0 0 1.57" xyz="0 0 0"/>
      <geometry>
        <mesh filename="package://robbie/meshes/F2.stl" scale="0.001 0.001 0.001"/>
      </geometry>
    </collision>
    <inertial>
      <mass value="0.02"/>
      <inertia ixx="0.001" ixy="0.0" ixz="0.0" iyy="0.001" iyz="0.0" izz="0.001"/>
    </inertial>
  </link>
  <gazebo reference="gripper_bracket_f2">
    <material>Gazebo/WhiteEmissive</material>
    <selfCollide>false</selfCollide>
    <turnGravityOff>true</turnGravityOff>
  </gazebo>
  <link name="right_finger_link">
    <visual>
      <origin rpy="1.57 0 1.57" xyz="0 0 0"/>
      <geometry>
        <box size="-0.08 0.005 0.035"/>
      </geometry>
      <material name="grey3">
        <color rgba="0.8 0.8 0.8 1.0"/>
      </material>
    </visual>
    <collision>
      <origin rpy="1.57 0 1.57" xyz="0 0 0"/>
      <geometry>
        <box size="-0.08 0.005 0.035"/>
      </geometry>
    </collision>
  </link>
  <gazebo reference="right_finger_link">
    <material>Gazebo/FlatBlack</material>
    <selfCollide>false</selfCollide>
    <turnGravityOff>true</turnGravityOff>
  </gazebo>
  <link name="left_finger_link">
    <visual>
      <origin rpy="1.57 0 1.57" xyz="0 0 0"/>
      <geometry>
        <box size="0.08 0.005 0.035"/>
      </geometry>
      <material name="blue1">
        <color rgba="0 0 0.9 1.0"/>
      </material>
    </visual>
    <collision>
      <origin rpy="1.57 0 1.57" xyz="0 0 0"/>
      <geometry>
        <box size="0.08 0.005 0.035"/>
      </geometry>
    </collision>
  </link>
  <gazebo reference="left_finger_link">
    <material>Gazebo/FlatBlack</material>
    <selfCollide>false</selfCollide>
    <turnGravityOff>true</turnGravityOff>
  </gazebo>
  <!-- head details-->
  <link name="head_tilt_bracket">
    <visual>
      <origin rpy="0 3.1415 0" xyz="0 0 0"/>
      <geometry>
        <mesh filename="package://robbie/meshes/F2.stl" scale="0.001 0.001 0.001"/>
      </geometry>
      <material name="bracket_color">
        <color rgba="0.9 0.9 0.9 1.0"/>
      </material>
    </visual>
    <collision>
      <origin rpy="0 3.1415 0" xyz="0 0 0"/>
      <geometry>
        <mesh filename="package://robbie/meshes/F2.stl" scale="0.001 0.001 0.001"/>
      </geometry>
    </collision>
    <inertial>
      <mass value="0.02"/>
      <inertia ixx="0.001" ixy="0.0" ixz="0.0" iyy="0.001" iyz="0.0" izz="0.001"/>
    </inertial>
  </link>
  <gazebo reference="head_tilt_bracket">
    <material>Gazebo/WhiteEmissive</material>
    <selfCollide>false</selfCollide>
    <turnGravityOff>true</turnGravityOff>
  </gazebo>
  <link name="head_tilt_link">
    <visual>
      <origin rpy="3.1415 0 0" xyz="0 0 0"/>
      <geometry>
        <mesh filename="package://robbie/meshes/ax12_box2.stl" scale="0.001 0.001 0.001"/>
      </geometry>
      <material name="ax12_color">
        <color rgba="0.1 0.1 0.1 1.0"/>
      </material>
    </visual>
    <collision>
      <origin rpy="3.1415 0 0" xyz="0 0 0"/>
      <geometry>
        <!--<box size="0.032 0.038 0.05" />-->
        <mesh filename="package://robbie/meshes/ax12_box2.stl" scale="0.001 0.001 0.001"/>
      </geometry>
    </collision>
    <inertial>
      <mass value="0.055"/>
      <inertia ixx="0.001" ixy="0.0" ixz="0.0" iyy="0.001" iyz="0.0" izz="0.001"/>
    </inertial>
  </link>
  <gazebo reference="head_tilt_link">
    <material>Gazebo/FlatBlack</material>
    <selfCollide>false</selfCollide>
    <turnGravityOff>true</turnGravityOff>
  </gazebo>
  <link name="head_pan_bracket">
    <visual>
      <origin rpy="0 0 0" xyz="0 0 0"/>
      <geometry>
        <mesh filename="package://robbie/meshes/F3.stl" scale="0.001 0.001 0.001"/>
      </geometry>
      <material name="grey1">
        <color rgba="0.75 0.75 0.75 1.0"/>
      </material>
      <material name="bracket_color">
        <color rgba="0.9 0.9 0.9 1.0"/>
      </material>
    </visual>
    <collision>
      <origin rpy="0 0 0" xyz="0 0 0"/>
      <geometry>
        <mesh filename="package://robbie/meshes/F3.stl" scale="0.001 0.001 0.001"/>
      </geometry>
    </collision>
    <inertial>
      <mass value="0.01"/>
      <inertia ixx="0.001" ixy="0.0" ixz="0.0" iyy="0.001" iyz="0.0" izz="0.001"/>
    </inertial>
  </link>
  <gazebo reference="head_pan_bracket">
    <material>Gazebo/WhiteEmissive</material>
    <selfCollide>false</selfCollide>
    <turnGravityOff>true</turnGravityOff>
  </gazebo>
  <link name="head_pan_link">
    <visual>
      <origin rpy=" 1.57 0 1.57" xyz="0 0 0"/>
      <geometry>
        <mesh filename="package://robbie/meshes/ax12_box2.stl" scale="0.001 0.001 0.001"/>
      </geometry>
      <material name="ax12_color">
        <color rgba="0.1 0.1 0.1 1.0"/>
      </material>
    </visual>
    <collision>
      <origin rpy=" 1.57 0 1.57" xyz="0 0 0"/>
      <geometry>
        <!--<box size="0.032 0.038 0.05" />-->
        <mesh filename="package://robbie/meshes/ax12_box2.stl" scale="0.001 0.001 0.001"/>
      </geometry>
    </collision>
    <inertial>
      <mass value="0.055"/>
      <inertia ixx="0.001" ixy="0.0" ixz="0.0" iyy="0.001" iyz="0.0" izz="0.001"/>
    </inertial>
  </link>
  <gazebo reference="head_pan_link">
    <material>Gazebo/FlatBlack</material>
    <selfCollide>false</selfCollide>
    <turnGravityOff>true</turnGravityOff>
  </gazebo>
  <link name="neck_link">
    <visual>
      <origin rpy="1.57 0 -1.570" xyz="0 0 0"/>
      <geometry>
        <mesh filename="package://robbie/meshes/F3.stl" scale="0.001 0.001 0.001"/>
      </geometry>
      <material name="grey1">
        <color rgba="0.75 0.75 0.75 1.0"/>
      </material>
      <material name="bracket_color">
        <color rgba="0.9 0.9 0.9 1.0"/>
      </material>
    </visual>
    <collision>
      <origin rpy="1.57 0 -1.570" xyz="0 0 0"/>
      <geometry>
        <mesh filename="package://robbie/meshes/F3.stl" scale="0.001 0.001 0.001"/>
      </geometry>
    </collision>
    <inertial>
      <mass value="0.01"/>
      <inertia ixx="0.001" ixy="0.0" ixz="0.0" iyy="0.001" iyz="0.0" izz="0.001"/>
    </inertial>
  </link>
  <gazebo reference="neck_link">
    <material>Gazebo/WhiteEmissive</material>
    <selfCollide>false</selfCollide>
    <turnGravityOff>true</turnGravityOff>
  </gazebo>
  <link name="head_base_link">
    <visual>
      <origin rpy="0 0 0" xyz="0 0 0"/>
      <geometry>
        <box size="0.06 0.08 0.005"/>
      </geometry>
      <material name="black">
        <color rgba="0.1 0.1 0.1 1.0"/>
      </material>
    </visual>
    <collision>
      <origin rpy="0 0 0" xyz="0 0 0"/>
      <geometry>
        <box size="0.06 0.08 0.005"/>
      </geometry>
    </collision>
  </link>
  <gazebo reference="head_base_link">
    <material>Gazebo/FlatBlack</material>
    <selfCollide>false</selfCollide>
    <turnGravityOff>true</turnGravityOff>
  </gazebo>
  <link name="kinect_link">
    <inertial>
      <mass value="1.0"/>
      <origin xyz="0 0 0"/>
      <inertia ixx="1.0" ixy="0.0" ixz="0.0" iyy="1.0" iyz="0.0" izz="1.0"/>
    </inertial>
    <visual>
      <origin rpy="0 0 0" xyz=" 0 0 0 "/>
      <geometry>
        <mesh filename="package://robbie/meshes/kinect.stl" scale="0.001 0.001 0.001"/>
      </geometry>
      <material name="ax12_color">
        <color rgba="0.1 0.1 0.1 1.0"/>
      </material>
    </visual>
    <collision>
      <origin rpy="0 0 0" xyz="0 0 0"/>
      <geometry>
        <mesh filename="package://robbie/meshes/kinect.stl" scale="0.001 0.001 0.001"/>
      </geometry>
    </collision>
  </link>
  <link name="head_cam_link">
    <inertial>
      <mass value="1.0"/>
      <origin xyz="0 0 0"/>
      <inertia ixx="1.0" ixy="0.0" ixz="0.0" iyy="1.0" iyz="0.0" izz="1.0"/>
    </inertial>
    <visual>
      <origin rpy="0 0 0" xyz=" 0 0 0 "/>
      <geometry>
        <mesh filename="package://robbie/meshes/kinect.stl" scale="0.001 0.001 0.001"/>
      </geometry>
      <material name="grey3">
        <color rgba="0.8 0.8 0.8 1.0"/>
      </material>
    </visual>
    <collision>
      <origin rpy="0 0 0" xyz="0 0 0"/>
      <geometry>
        <mesh filename="package://robbie/meshes/kinect.stl" scale="0.001 0.001 0.001"/>
      </geometry>
    </collision>
  </link>
  <link name="head_link">
    <visual>
      <geometry>
        <mesh filename="package://robbie/meshes/head.stl" scale="0.001 0.001 0.001"/>
      </geometry>
      <material name="grey1">
        <color rgba="0.75 0.75 0.75 1.0"/>
      </material>
      <origin rpy="1.57 0 1.57" xyz="0 0 0"/>
    </visual>
  </link>
  <link name="head_link_fake">
    <inertial>
      <mass value="0.0001"/>
      <origin xyz="0 0 0"/>
      <inertia ixx="0.0001" ixy="0.0" ixz="0.0" iyy="0.0001" iyz="0.0" izz="0.0001"/>
    </inertial>
  </link>
  <link name="chest_link">
    <visual>
      <geometry>
        <mesh filename="package://robbie/meshes/torso.stl" scale="0.001 0.001 0.001"/>
      </geometry>
      <material name="grey1">
        <color rgba="0.75 0.75 0.75 1.0"/>
      </material>
      <origin rpy="1.57 0 1.57" xyz="0 0 0"/>
    </visual>
  </link>
  <!-- =================== Joint Definitions ==================== -->
  <joint name="base_link_joint" type="fixed">
    <parent link="base_link"/>
    <child link="deck_link"/>
    <origin rpy="0 0 0" xyz="-0.10 0 .36"/>
  </joint>
  <joint name="left_wheel_joint" type="fixed">
    <parent link="base_link"/>
    <child link="left_wheel"/>
    <origin rpy="0 0 0" xyz="0.1 -0.2 0.1"/>
  </joint>
  <joint name="right_wheel_joint" type="fixed">
    <parent link="base_link"/>
    <child link="right_wheel"/>
    <origin rpy="0 0 0" xyz="0.1 0.2 0.1"/>
  </joint>
  <joint name="castor_wheel_joint_l" type="fixed">
    <parent link="base_link"/>
    <child link="castor_wheel_l"/>
    <origin rpy="0 0 0" xyz="-0.20 -0.13 0.05"/>
  </joint>
  <joint name="castor_wheel_joint_r" type="fixed">
    <parent link="base_link"/>
    <child link="castor_wheel_r"/>
    <origin rpy="0 0 0" xyz="-0.20 0.13 0.05"/>
  </joint>
  <joint name="chest_joint" type="fixed">
    <parent link="deck_link"/>
    <child link="chest_link"/>
    <origin rpy="0 0 0" xyz="0.18 0.085 .48"/>
  </joint>
  <joint name="torso_joint" type="fixed">
    <parent link="deck_link"/>
    <child link="torso_link"/>
    <origin rpy="0 0 0" xyz="0.1 0 0.38"/>
  </joint>
  <joint name="imu_joint" type="fixed">
    <parent link="base_link"/>
    <child link="imu_link"/>
    <origin rpy="0 0 0" xyz="-0. 0 0.25"/>
  </joint>
  <!--#############################right arm Joints###################################-->
  <joint name="right_arm_tilt_joint" type="revolute">
    <parent link="chest_link"/>
    <child link="right_arm_tilt_link"/>
    <origin rpy="-1.57 0 0" xyz="-0.02 -0.24 0.12"/>
    <axis xyz="1 0 0"/>
    <limit effort="10" lower="0" upper="1.57" velocity="0"/>
  </joint>
  <joint name="right_arm_lift_joint" type="revolute">
    <parent link="right_arm_tilt_link"/>
    <child link="right_lift_link"/>
    <origin rpy="0 0 0" xyz="-0.015 -0.058 -0.03"/>
    <axis xyz="0 1 0"/>
    <limit effort="10" lower="-1.57" upper="1.8" velocity="0"/>
  </joint>
  <joint name="right_bicep" type="fixed">
    <parent link="right_lift_link"/>
    <child link="shoulder_bracket_link"/>
    <origin rpy="0 0 0" xyz="-0.05 -0.04 0.05"/>
    <!--pitch will adjust bicep angle0.9  x is in out y is- down-->
  </joint>
  <joint name="right_rotate_gear" type="fixed">
    <parent link="shoulder_bracket_link"/>
    <child link="right_rotate_link"/>
    <origin rpy="0 0 0 " xyz="0.085 0.045 -0.034"/>
  </joint>
  <joint name="right_arm_rotate_joint" type="revolute">
    <parent link="right_rotate_link"/>
    <child link="right_elbow_link"/>
    <origin rpy="-1.57 0 0 " xyz="0.115 -0.05 -0.0"/>
    <axis xyz="1 0 0"/>
    <limit effort="10" lower="-3.14" upper="0" velocity="0"/>
  </joint>
  <joint name="right_arm_elbow_joint" type="revolute">
    <parent link="right_elbow_link"/>
    <child link="right_forearm_link"/>
    <origin rpy="0 0 0" xyz="0.16 0 0."/>
    <axis xyz="0 0 1"/>
    <limit effort="10" lower="-1.57" upper="0.50" velocity="0"/>
  </joint>
  <!--right_arm_wrist_pan_joint-->
  <joint name="right_arm_wrist_pan_bracket" type="fixed">
    <parent link="right_forearm_link"/>
    <child link="wrist_pan_servo"/>
    <origin rpy="0 0 -1.57" xyz="0.3 0.02 0.025"/>
    <!--now-->
  </joint>
  <joint name="right_arm_wrist_pan_joint" type="revolute">
    <parent link="wrist_pan_servo"/>
    <child link="wrist_pan_servo_bracket_f3"/>
    <origin rpy="0 1.57 0" xyz="0. 0.015 0.0"/>
    <axis xyz="0 1 0"/>
    <limit effort="10" lower="-2.61" upper="2.61" velocity="0"/>
    <dynamics damping="0.0"/>
  </joint>
  <joint name="right_arm_wrist_tilt_bracket" type="fixed">
    <parent link="wrist_pan_servo_bracket_f3"/>
    <child link="wrist_tilt_servo"/>
    <origin rpy="0 0 0" xyz="0.04 0 0.0"/>
    <axis xyz="1 0 0"/>
  </joint>
  <!--wrist_tilt_joint-->
  <joint name="right_arm_wrist_tilt_joint" type="revolute">
    <parent link="wrist_tilt_servo"/>
    <child link="wrist_tilt_bracket_f2"/>
    <origin rpy="0 0 0" xyz="-0.04 0.05 0"/>
    <axis xyz="0 0 1"/>
    <limit effort="10" lower="-1.57" upper="1.57" velocity="0"/>
    <dynamics damping="0.0"/>
  </joint>
  <joint name="right_arm_gripper_bracket" type="fixed">
    <parent link="wrist_tilt_bracket_f2"/>
    <child link="gripper_bracket_f3"/>
    <origin rpy="0 0 0" xyz="0.0 0.025 0.015"/>
  </joint>
  <joint name="right_arm_gripper_servo" type="fixed">
    <parent link="gripper_bracket_f3"/>
    <child link="gripper_servo"/>
    <origin rpy="0 3.14 0" xyz="0.0 0.02 -0.02"/>
  </joint>
  <!-- gripper_joint-->
  <joint name="right_arm_gripper_joint" type="revolute">
    <parent link="gripper_servo"/>
    <child link="gripper_bracket_f2"/>
    <origin rpy="0 0 0" xyz="0 0.0 0.0"/>
    <axis xyz="1 0 0"/>
    <limit effort="10" lower="-0.36" upper="0.28" velocity="0"/>
    <dynamics damping="0.0"/>
  </joint>
  <joint name="right_arm_finger_link_l" type="fixed">
    <parent link="gripper_servo"/>
    <child link="left_finger_link"/>
    <origin rpy="0 0 0" xyz="0. 0.03 -0.04"/>
  </joint>
  <joint name="right_arm_finger_link_r" type="fixed">
    <parent link="gripper_bracket_f2"/>
    <child link="right_finger_link"/>
    <origin rpy="0 0 0" xyz="0 0.03 0.03"/>
  </joint>
  <!-- #####################################Head joints#########################################-->
  <joint name="head_tilt_servo" type="fixed">
    <parent link="torso_link"/>
    <child link="head_tilt_bracket"/>
    <origin rpy="0 0 0" xyz="0 0 0.27"/>
  </joint>
  <!-- Head tilt joint-->
  <joint name="head_tilt_mod_joint" type="revolute">
    <parent link="head_tilt_bracket"/>
    <child link="head_tilt_link"/>
    <origin rpy="0 0 0" xyz="0 0 0.0"/>
    <axis xyz="0 1 0"/>
    <limit effort="10" lower="-2.6" upper="2.6" velocity="0"/>
    <dynamics damping="0.0"/>
  </joint>
  <!-- Head tilt joint fake-->
  <joint name="head_tilt_joint" type="revolute">
    <parent link="head_tilt_bracket"/>
    <child link="head_link_fake"/>
    <origin rpy="0 0 0" xyz="0 0 0.0"/>
    <axis xyz="0 1 0"/>
    <limit effort="10" lower="-2.6" upper="2.6" velocity="0"/>
    <dynamics damping="0.0"/>
  </joint>
  <joint name="head_pan_servo" type="fixed">
    <parent link="head_tilt_link"/>
    <child link="head_pan_bracket"/>
    <origin rpy="0 0 0" xyz="-0.0 0 0.04"/>
  </joint>
  <!-- head_pan_joint-->
  <joint name="head_pan_joint" type="revolute">
    <parent link="head_pan_bracket"/>
    <child link="head_pan_link"/>
    <origin rpy="0 0 0" xyz="0.0 0 0.02"/>
    <origin rpy="0 0 0" xyz="0 0 0.0"/>
    <axis xyz="0 0 1"/>
    <limit effort="10" lower="-2" upper="2" velocity="0"/>
    <dynamics damping="0.0"/>
  </joint>
  <joint name="head_neck_link" type="fixed">
    <parent link="head_pan_link"/>
    <child link="neck_link"/>
    <origin rpy="0 0 0" xyz="-0.04 0 0.0"/>
  </joint>
  <joint name="neck_joint" type="fixed">
    <parent link="neck_link"/>
    <child link="head_base_link"/>
    <origin rpy="0 0 0" xyz="0.02 0 0.0"/>
  </joint>
  <joint name="head_joint" type="fixed">
    <parent link="head_base_link"/>
    <child link="head_link"/>
    <origin rpy="0 0 0" xyz="-0.02 -0.097 -0.45"/>
  </joint>
  <joint name="kinect_joint" type="fixed">
    <parent link="torso_link"/>
    <child link="kinect_link"/>
    <origin rpy="0 0 0" xyz="0.2 0 -0.26"/>
  </joint>
  <joint name="kinect_depth_joint" type="fixed">
    <origin rpy="0 0 0" xyz="0 0.018 0"/>
    <parent link="kinect_link"/>
    <child link="kinect_depth_frame"/>
  </joint>
  <link name="kinect_depth_frame">
    <inertial>
      <mass value="0.0001"/>
      <origin xyz="0 0 0"/>
      <inertia ixx="0.0001" ixy="0.0" ixz="0.0" iyy="0.0001" iyz="0.0" izz="0.0001"/>
    </inertial>
  </link>
  <joint name="kinect_depth_optical_joint" type="fixed">
    <origin rpy="-1.570795 0 -1.570795" xyz="0 0 0"/>
    <parent link="kinect_link"/>
    <child link="kinect_depth_optical_frame"/>
  </joint>
  <link name="kinect_depth_optical_frame">
    <inertial>
      <mass value="0.0001"/>
      <origin xyz="0 0 0"/>
      <inertia ixx="0.0001" ixy="0.0" ixz="0.0" iyy="0.0001" iyz="0.0" izz="0.0001"/>
    </inertial>
  </link>
  <joint name="kinect_rgb_optical_joint" type="fixed">
    <origin rpy="-1.570795 0 -1.570795" xyz="0 0 0"/>
    <parent link="kinect_depth_optical_frame"/>
    <child link="kinect_rgb_optical_frame"/>
  </joint>
  <link name="kinect_rgb_optical_frame">
    <inertial>
      <mass value="0.001"/>
      <origin xyz="0 0 0"/>
      <inertia ixx="0.0001" ixy="0.0" ixz="0.0" iyy="0.0001" iyz="0.0" izz="0.0001"/>
    </inertial>
  </link>
  <joint name="head_cam_joint" type="fixed">
    <parent link="head_link"/>
    <child link="head_cam_link"/>
    <origin rpy="0 0 0" xyz="0.15 0.1 0.58"/>
  </joint>
  <joint name="head_cam_depth_joint" type="fixed">
    <origin rpy="0 0 0" xyz="0 0.018 0"/>
    <parent link="head_cam_link"/>
    <child link="head_cam_depth_frame"/>
  </joint>
  <link name="head_cam_depth_frame">
    <inertial>
      <mass value="0.0001"/>
      <origin xyz="0 0 0"/>
      <inertia ixx="0.0001" ixy="0.0" ixz="0.0" iyy="0.0001" iyz="0.0" izz="0.0001"/>
    </inertial>
  </link>
  <joint name="head_cam_depth_optical_joint" type="fixed">
    <origin rpy="-1.570795 0 -1.570795" xyz="0 0 0"/>
    <parent link="head_cam_link"/>
    <child link="head_cam_depth_optical_frame"/>
  </joint>
  <link name="head_cam_depth_optical_frame">
    <inertial>
      <mass value="0.0001"/>
      <origin xyz="0 0 0"/>
      <inertia ixx="0.0001" ixy="0.0" ixz="0.0" iyy="0.0001" iyz="0.0" izz="0.0001"/>
    </inertial>
  </link>
  <joint name="head_cam_rgb_optical_joint" type="fixed">
    <origin rpy="-1.570795 0 -1.570795" xyz="0 0 0"/>
    <parent link="head_cam_depth_optical_frame"/>
    <child link="head_cam_rgb_optical_frame"/>
  </joint>
  <link name="head_cam_rgb_optical_frame">
    <inertial>
      <mass value="0.001"/>
      <origin xyz="0 0 0"/>
      <inertia ixx="0.0001" ixy="0.0" ixz="0.0" iyy="0.0001" iyz="0.0" izz="0.0001"/>
    </inertial>
  </link>
  <gazebo reference="robbie">
  	</gazebo>
</robot>
